+ module unload mvapich2_ib/2.3.2
++ /usr/bin/modulecmd bash unload mvapich2_ib/2.3.2
+ eval LD_LIBRARY_PATH=/opt/intel/2018.1.163/compilers_and_libraries_2018.1.163/linux/compiler/lib/intel64_lin:/opt/intel/2018.1.163/compilers_and_libraries_2018.1.163/linux/ipp/../compiler/lib/intel64:/opt/intel/2018.1.163/compilers_and_libraries_2018.1.163/linux/ipp/lib/intel64:/opt/intel/2018.1.163/compilers_and_libraries_2018.1.163/linux/mkl/lib/intel64:/opt/intel/2018.1.163/compilers_and_libraries_2018.1.163/linux/tbb/lib/intel64/gcc4.4 ';export' 'LD_LIBRARY_PATH;LOADEDMODULES=intel/2018.1.163' ';export' 'LOADEDMODULES;PATH=/home/edisj/anaconda3/bin:/home/edisj/anaconda3/condabin:/opt/intel/2018.1.163/compilers_and_libraries_2018.1.163/linux/bin/intel64:/usr/lib64/qt-3.3/bin:/usr/local/bin:/bin:/usr/bin:/usr/bin:/usr/local/sbin:/usr/sbin:/opt/sdsc/bin:/opt/sdsc/sbin:/opt/ibutils/bin:/opt/pdsh/bin:/opt/rocks/bin:/opt/rocks/sbin:/home/edisj/bin' ';export' 'PATH;_LMFILES_=/opt/modulefiles/compilers/intel/2018.1.163' ';export' '_LMFILES_;unset' 'MPIHOME;'
++ LD_LIBRARY_PATH=/opt/intel/2018.1.163/compilers_and_libraries_2018.1.163/linux/compiler/lib/intel64_lin:/opt/intel/2018.1.163/compilers_and_libraries_2018.1.163/linux/ipp/../compiler/lib/intel64:/opt/intel/2018.1.163/compilers_and_libraries_2018.1.163/linux/ipp/lib/intel64:/opt/intel/2018.1.163/compilers_and_libraries_2018.1.163/linux/mkl/lib/intel64:/opt/intel/2018.1.163/compilers_and_libraries_2018.1.163/linux/tbb/lib/intel64/gcc4.4
++ export LD_LIBRARY_PATH
++ LOADEDMODULES=intel/2018.1.163
++ export LOADEDMODULES
++ PATH=/home/edisj/anaconda3/bin:/home/edisj/anaconda3/condabin:/opt/intel/2018.1.163/compilers_and_libraries_2018.1.163/linux/bin/intel64:/usr/lib64/qt-3.3/bin:/usr/local/bin:/bin:/usr/bin:/usr/bin:/usr/local/sbin:/usr/sbin:/opt/sdsc/bin:/opt/sdsc/sbin:/opt/ibutils/bin:/opt/pdsh/bin:/opt/rocks/bin:/opt/rocks/sbin:/home/edisj/bin
++ export PATH
++ _LMFILES_=/opt/modulefiles/compilers/intel/2018.1.163
++ export _LMFILES_
++ unset MPIHOME
+ module load openmpi_ib/3.1.4
++ /usr/bin/modulecmd bash load openmpi_ib/3.1.4
+ eval LD_LIBRARY_PATH=/opt/openmpi/intel/ib/lib:/opt/intel/2018.1.163/compilers_and_libraries_2018.1.163/linux/compiler/lib/intel64_lin:/opt/intel/2018.1.163/compilers_and_libraries_2018.1.163/linux/ipp/../compiler/lib/intel64:/opt/intel/2018.1.163/compilers_and_libraries_2018.1.163/linux/ipp/lib/intel64:/opt/intel/2018.1.163/compilers_and_libraries_2018.1.163/linux/mkl/lib/intel64:/opt/intel/2018.1.163/compilers_and_libraries_2018.1.163/linux/tbb/lib/intel64/gcc4.4 ';export' 'LD_LIBRARY_PATH;LOADEDMODULES=intel/2018.1.163:openmpi_ib/3.1.4' ';export' 'LOADEDMODULES;MPIHOME=/opt/openmpi/intel/ib' ';export' 'MPIHOME;OMPI_MCA_mpi_cuda_support=0' ';export' 'OMPI_MCA_mpi_cuda_support;PATH=/opt/openmpi/intel/ib/bin:/home/edisj/anaconda3/bin:/home/edisj/anaconda3/condabin:/opt/intel/2018.1.163/compilers_and_libraries_2018.1.163/linux/bin/intel64:/usr/lib64/qt-3.3/bin:/usr/local/bin:/bin:/usr/bin:/usr/bin:/usr/local/sbin:/usr/sbin:/opt/sdsc/bin:/opt/sdsc/sbin:/opt/ibutils/bin:/opt/pdsh/bin:/opt/rocks/bin:/opt/rocks/sbin:/home/edisj/bin' ';export' 'PATH;_LMFILES_=/opt/modulefiles/compilers/intel/2018.1.163:/opt/modulefiles/mpi/openmpi_ib/3.1.4' ';export' '_LMFILES_;'
++ LD_LIBRARY_PATH=/opt/openmpi/intel/ib/lib:/opt/intel/2018.1.163/compilers_and_libraries_2018.1.163/linux/compiler/lib/intel64_lin:/opt/intel/2018.1.163/compilers_and_libraries_2018.1.163/linux/ipp/../compiler/lib/intel64:/opt/intel/2018.1.163/compilers_and_libraries_2018.1.163/linux/ipp/lib/intel64:/opt/intel/2018.1.163/compilers_and_libraries_2018.1.163/linux/mkl/lib/intel64:/opt/intel/2018.1.163/compilers_and_libraries_2018.1.163/linux/tbb/lib/intel64/gcc4.4
++ export LD_LIBRARY_PATH
++ LOADEDMODULES=intel/2018.1.163:openmpi_ib/3.1.4
++ export LOADEDMODULES
++ MPIHOME=/opt/openmpi/intel/ib
++ export MPIHOME
++ OMPI_MCA_mpi_cuda_support=0
++ export OMPI_MCA_mpi_cuda_support
++ PATH=/opt/openmpi/intel/ib/bin:/home/edisj/anaconda3/bin:/home/edisj/anaconda3/condabin:/opt/intel/2018.1.163/compilers_and_libraries_2018.1.163/linux/bin/intel64:/usr/lib64/qt-3.3/bin:/usr/local/bin:/bin:/usr/bin:/usr/bin:/usr/local/sbin:/usr/sbin:/opt/sdsc/bin:/opt/sdsc/sbin:/opt/ibutils/bin:/opt/pdsh/bin:/opt/rocks/bin:/opt/rocks/sbin:/home/edisj/bin
++ export PATH
++ _LMFILES_=/opt/modulefiles/compilers/intel/2018.1.163:/opt/modulefiles/mpi/openmpi_ib/3.1.4
++ export _LMFILES_
+ module load hdf5/1.10.3
++ /usr/bin/modulecmd bash load hdf5/1.10.3
+ eval HDF5HOME=/opt/hdf5/1.10.3/intel/openmpi_ib ';export' 'HDF5HOME;LD_LIBRARY_PATH=/opt/hdf5/1.10.3/intel/openmpi_ib/lib:/opt/openmpi/intel/ib/lib:/opt/intel/2018.1.163/compilers_and_libraries_2018.1.163/linux/compiler/lib/intel64_lin:/opt/intel/2018.1.163/compilers_and_libraries_2018.1.163/linux/ipp/../compiler/lib/intel64:/opt/intel/2018.1.163/compilers_and_libraries_2018.1.163/linux/ipp/lib/intel64:/opt/intel/2018.1.163/compilers_and_libraries_2018.1.163/linux/mkl/lib/intel64:/opt/intel/2018.1.163/compilers_and_libraries_2018.1.163/linux/tbb/lib/intel64/gcc4.4' ';export' 'LD_LIBRARY_PATH;LIBPATH=/opt/hdf5/1.10.3/intel/openmpi_ib/lib' ';export' 'LIBPATH;LOADEDMODULES=intel/2018.1.163:openmpi_ib/3.1.4:hdf5/1.10.3' ';export' 'LOADEDMODULES;PATH=/opt/hdf5/1.10.3/intel/openmpi_ib/bin:/opt/openmpi/intel/ib/bin:/home/edisj/anaconda3/bin:/home/edisj/anaconda3/condabin:/opt/intel/2018.1.163/compilers_and_libraries_2018.1.163/linux/bin/intel64:/usr/lib64/qt-3.3/bin:/usr/local/bin:/bin:/usr/bin:/usr/bin:/usr/local/sbin:/usr/sbin:/opt/sdsc/bin:/opt/sdsc/sbin:/opt/ibutils/bin:/opt/pdsh/bin:/opt/rocks/bin:/opt/rocks/sbin:/home/edisj/bin' ';export' 'PATH;_LMFILES_=/opt/modulefiles/compilers/intel/2018.1.163:/opt/modulefiles/mpi/openmpi_ib/3.1.4:/opt/modulefiles/applications/hdf5/1.10.3' ';export' '_LMFILES_;'
++ HDF5HOME=/opt/hdf5/1.10.3/intel/openmpi_ib
++ export HDF5HOME
++ LD_LIBRARY_PATH=/opt/hdf5/1.10.3/intel/openmpi_ib/lib:/opt/openmpi/intel/ib/lib:/opt/intel/2018.1.163/compilers_and_libraries_2018.1.163/linux/compiler/lib/intel64_lin:/opt/intel/2018.1.163/compilers_and_libraries_2018.1.163/linux/ipp/../compiler/lib/intel64:/opt/intel/2018.1.163/compilers_and_libraries_2018.1.163/linux/ipp/lib/intel64:/opt/intel/2018.1.163/compilers_and_libraries_2018.1.163/linux/mkl/lib/intel64:/opt/intel/2018.1.163/compilers_and_libraries_2018.1.163/linux/tbb/lib/intel64/gcc4.4
++ export LD_LIBRARY_PATH
++ LIBPATH=/opt/hdf5/1.10.3/intel/openmpi_ib/lib
++ export LIBPATH
++ LOADEDMODULES=intel/2018.1.163:openmpi_ib/3.1.4:hdf5/1.10.3
++ export LOADEDMODULES
++ PATH=/opt/hdf5/1.10.3/intel/openmpi_ib/bin:/opt/openmpi/intel/ib/bin:/home/edisj/anaconda3/bin:/home/edisj/anaconda3/condabin:/opt/intel/2018.1.163/compilers_and_libraries_2018.1.163/linux/bin/intel64:/usr/lib64/qt-3.3/bin:/usr/local/bin:/bin:/usr/bin:/usr/bin:/usr/local/sbin:/usr/sbin:/opt/sdsc/bin:/opt/sdsc/sbin:/opt/ibutils/bin:/opt/pdsh/bin:/opt/rocks/bin:/opt/rocks/sbin:/home/edisj/bin
++ export PATH
++ _LMFILES_=/opt/modulefiles/compilers/intel/2018.1.163:/opt/modulefiles/mpi/openmpi_ib/3.1.4:/opt/modulefiles/applications/hdf5/1.10.3
++ export _LMFILES_
+ source activate mda8
++ _CONDA_ROOT=/home/edisj/anaconda3
++ . /home/edisj/anaconda3/etc/profile.d/conda.sh
+++ export CONDA_EXE=/home/edisj/anaconda3/bin/conda
+++ CONDA_EXE=/home/edisj/anaconda3/bin/conda
+++ export _CE_M=
+++ _CE_M=
+++ export _CE_CONDA=
+++ _CE_CONDA=
+++ export CONDA_PYTHON_EXE=/home/edisj/anaconda3/bin/python
+++ CONDA_PYTHON_EXE=/home/edisj/anaconda3/bin/python
+++ '[' -z x ']'
++ conda activate mda8
++ '[' 2 -lt 1 ']'
++ local cmd=activate
++ shift
++ case "$cmd" in
++ __conda_activate activate mda8
++ '[' -n '' ']'
++ local cmd=activate
++ shift
++ local ask_conda
++ CONDA_INTERNAL_OLDPATH=/opt/hdf5/1.10.3/intel/openmpi_ib/bin:/opt/openmpi/intel/ib/bin:/home/edisj/anaconda3/bin:/home/edisj/anaconda3/condabin:/opt/intel/2018.1.163/compilers_and_libraries_2018.1.163/linux/bin/intel64:/usr/lib64/qt-3.3/bin:/usr/local/bin:/bin:/usr/bin:/usr/bin:/usr/local/sbin:/usr/sbin:/opt/sdsc/bin:/opt/sdsc/sbin:/opt/ibutils/bin:/opt/pdsh/bin:/opt/rocks/bin:/opt/rocks/sbin:/home/edisj/bin
++ __add_sys_prefix_to_path
++ '[' -n '' ']'
+++ dirname /home/edisj/anaconda3/bin/conda
++ SYSP=/home/edisj/anaconda3/bin
+++ dirname /home/edisj/anaconda3/bin
++ SYSP=/home/edisj/anaconda3
++ '[' -n '' ']'
++ PATH=/home/edisj/anaconda3/bin:/opt/hdf5/1.10.3/intel/openmpi_ib/bin:/opt/openmpi/intel/ib/bin:/home/edisj/anaconda3/bin:/home/edisj/anaconda3/condabin:/opt/intel/2018.1.163/compilers_and_libraries_2018.1.163/linux/bin/intel64:/usr/lib64/qt-3.3/bin:/usr/local/bin:/bin:/usr/bin:/usr/bin:/usr/local/sbin:/usr/sbin:/opt/sdsc/bin:/opt/sdsc/sbin:/opt/ibutils/bin:/opt/pdsh/bin:/opt/rocks/bin:/opt/rocks/sbin:/home/edisj/bin
++ export PATH
+++ PS1=
+++ /home/edisj/anaconda3/bin/conda shell.posix activate mda8
++ ask_conda='PS1='\''(mda8) '\''
export PATH='\''/opt/hdf5/1.10.3/intel/openmpi_ib/bin:/opt/openmpi/intel/ib/bin:/home/edisj/anaconda3/envs/mda8/bin:/home/edisj/anaconda3/condabin:/opt/intel/2018.1.163/compilers_and_libraries_2018.1.163/linux/bin/intel64:/usr/lib64/qt-3.3/bin:/usr/local/bin:/bin:/usr/bin:/usr/bin:/usr/local/sbin:/usr/sbin:/opt/sdsc/bin:/opt/sdsc/sbin:/opt/ibutils/bin:/opt/pdsh/bin:/opt/rocks/bin:/opt/rocks/sbin:/home/edisj/bin'\''
export CONDA_PREFIX='\''/home/edisj/anaconda3/envs/mda8'\''
export CONDA_SHLVL='\''2'\''
export CONDA_DEFAULT_ENV='\''mda8'\''
export CONDA_PROMPT_MODIFIER='\''(mda8) '\''
export CONDA_EXE='\''/home/edisj/anaconda3/bin/conda'\''
export _CE_M='\'''\''
export _CE_CONDA='\'''\''
export CONDA_PYTHON_EXE='\''/home/edisj/anaconda3/bin/python'\''
export CONDA_PREFIX_1='\''/home/edisj/anaconda3'\'''
++ rc=0
++ PATH=/opt/hdf5/1.10.3/intel/openmpi_ib/bin:/opt/openmpi/intel/ib/bin:/home/edisj/anaconda3/bin:/home/edisj/anaconda3/condabin:/opt/intel/2018.1.163/compilers_and_libraries_2018.1.163/linux/bin/intel64:/usr/lib64/qt-3.3/bin:/usr/local/bin:/bin:/usr/bin:/usr/bin:/usr/local/sbin:/usr/sbin:/opt/sdsc/bin:/opt/sdsc/sbin:/opt/ibutils/bin:/opt/pdsh/bin:/opt/rocks/bin:/opt/rocks/sbin:/home/edisj/bin
++ eval 'PS1='\''(mda8) '\''
export PATH='\''/opt/hdf5/1.10.3/intel/openmpi_ib/bin:/opt/openmpi/intel/ib/bin:/home/edisj/anaconda3/envs/mda8/bin:/home/edisj/anaconda3/condabin:/opt/intel/2018.1.163/compilers_and_libraries_2018.1.163/linux/bin/intel64:/usr/lib64/qt-3.3/bin:/usr/local/bin:/bin:/usr/bin:/usr/bin:/usr/local/sbin:/usr/sbin:/opt/sdsc/bin:/opt/sdsc/sbin:/opt/ibutils/bin:/opt/pdsh/bin:/opt/rocks/bin:/opt/rocks/sbin:/home/edisj/bin'\''
export CONDA_PREFIX='\''/home/edisj/anaconda3/envs/mda8'\''
export CONDA_SHLVL='\''2'\''
export CONDA_DEFAULT_ENV='\''mda8'\''
export CONDA_PROMPT_MODIFIER='\''(mda8) '\''
export CONDA_EXE='\''/home/edisj/anaconda3/bin/conda'\''
export _CE_M='\'''\''
export _CE_CONDA='\'''\''
export CONDA_PYTHON_EXE='\''/home/edisj/anaconda3/bin/python'\''
export CONDA_PREFIX_1='\''/home/edisj/anaconda3'\'''
+++ PS1='(mda8) '
+++ export PATH=/opt/hdf5/1.10.3/intel/openmpi_ib/bin:/opt/openmpi/intel/ib/bin:/home/edisj/anaconda3/envs/mda8/bin:/home/edisj/anaconda3/condabin:/opt/intel/2018.1.163/compilers_and_libraries_2018.1.163/linux/bin/intel64:/usr/lib64/qt-3.3/bin:/usr/local/bin:/bin:/usr/bin:/usr/bin:/usr/local/sbin:/usr/sbin:/opt/sdsc/bin:/opt/sdsc/sbin:/opt/ibutils/bin:/opt/pdsh/bin:/opt/rocks/bin:/opt/rocks/sbin:/home/edisj/bin
+++ PATH=/opt/hdf5/1.10.3/intel/openmpi_ib/bin:/opt/openmpi/intel/ib/bin:/home/edisj/anaconda3/envs/mda8/bin:/home/edisj/anaconda3/condabin:/opt/intel/2018.1.163/compilers_and_libraries_2018.1.163/linux/bin/intel64:/usr/lib64/qt-3.3/bin:/usr/local/bin:/bin:/usr/bin:/usr/bin:/usr/local/sbin:/usr/sbin:/opt/sdsc/bin:/opt/sdsc/sbin:/opt/ibutils/bin:/opt/pdsh/bin:/opt/rocks/bin:/opt/rocks/sbin:/home/edisj/bin
+++ export CONDA_PREFIX=/home/edisj/anaconda3/envs/mda8
+++ CONDA_PREFIX=/home/edisj/anaconda3/envs/mda8
+++ export CONDA_SHLVL=2
+++ CONDA_SHLVL=2
+++ export CONDA_DEFAULT_ENV=mda8
+++ CONDA_DEFAULT_ENV=mda8
+++ export 'CONDA_PROMPT_MODIFIER=(mda8) '
+++ CONDA_PROMPT_MODIFIER='(mda8) '
+++ export CONDA_EXE=/home/edisj/anaconda3/bin/conda
+++ CONDA_EXE=/home/edisj/anaconda3/bin/conda
+++ export _CE_M=
+++ _CE_M=
+++ export _CE_CONDA=
+++ _CE_CONDA=
+++ export CONDA_PYTHON_EXE=/home/edisj/anaconda3/bin/python
+++ CONDA_PYTHON_EXE=/home/edisj/anaconda3/bin/python
+++ export CONDA_PREFIX_1=/home/edisj/anaconda3
+++ CONDA_PREFIX_1=/home/edisj/anaconda3
++ '[' 0 '!=' 0 ']'
++ __conda_hashr
++ '[' -n '' ']'
++ '[' -n '' ']'
++ hash -r
+ testdir=/oasis/scratch/comet/edisj/temp_project/stripe24/38386559
+ export OMP_NUM_THREADS=1
+ OMP_NUM_THREADS=1
+ ibrun -np 48 python -W ignore /oasis/projects/nsf/azs119/edisj/Comet/benchmarks/vanilla_stripe/scripts/24/benchmark.py /oasis/scratch/comet/edisj/temp_project/stripe24/38386559/YiiP_system.pdb /oasis/scratch/comet/edisj/temp_project/stripe24/38386559/YiiP_system_9ns_center100x.h5md run1/2node_3
Traceback (most recent call last):
  File "/oasis/projects/nsf/azs119/edisj/Comet/benchmarks/vanilla_stripe/scripts/24/benchmark.py", line 204, in <module>
    times_array, rmsd_array = benchmark(topology, trajectory)
  File "/oasis/projects/nsf/azs119/edisj/Comet/benchmarks/vanilla_stripe/scripts/24/benchmark.py", line 58, in benchmark
    rmsd_array[i] = rmsd(CA.positions, x_ref, superposition=True)
IndexError: index 1877 is out of bounds for axis 0 with size 1877
Traceback (most recent call last):
  File "/oasis/projects/nsf/azs119/edisj/Comet/benchmarks/vanilla_stripe/scripts/24/benchmark.py", line 204, in <module>
    times_array, rmsd_array = benchmark(topology, trajectory)
  File "/oasis/projects/nsf/azs119/edisj/Comet/benchmarks/vanilla_stripe/scripts/24/benchmark.py", line 58, in benchmark
    rmsd_array[i] = rmsd(CA.positions, x_ref, superposition=True)
IndexError: index 1877 is out of bounds for axis 0 with size 1877
Traceback (most recent call last):
  File "/oasis/projects/nsf/azs119/edisj/Comet/benchmarks/vanilla_stripe/scripts/24/benchmark.py", line 204, in <module>
    times_array, rmsd_array = benchmark(topology, trajectory)
  File "/oasis/projects/nsf/azs119/edisj/Comet/benchmarks/vanilla_stripe/scripts/24/benchmark.py", line 58, in benchmark
    rmsd_array[i] = rmsd(CA.positions, x_ref, superposition=True)
IndexError: index 1877 is out of bounds for axis 0 with size 1877
Traceback (most recent call last):
  File "/oasis/projects/nsf/azs119/edisj/Comet/benchmarks/vanilla_stripe/scripts/24/benchmark.py", line 204, in <module>
    times_array, rmsd_array = benchmark(topology, trajectory)
  File "/oasis/projects/nsf/azs119/edisj/Comet/benchmarks/vanilla_stripe/scripts/24/benchmark.py", line 58, in benchmark
    rmsd_array[i] = rmsd(CA.positions, x_ref, superposition=True)
IndexError: index 1877 is out of bounds for axis 0 with size 1877
Traceback (most recent call last):
  File "/oasis/projects/nsf/azs119/edisj/Comet/benchmarks/vanilla_stripe/scripts/24/benchmark.py", line 204, in <module>
    times_array, rmsd_array = benchmark(topology, trajectory)
  File "/oasis/projects/nsf/azs119/edisj/Comet/benchmarks/vanilla_stripe/scripts/24/benchmark.py", line 58, in benchmark
    rmsd_array[i] = rmsd(CA.positions, x_ref, superposition=True)
IndexError: index 1877 is out of bounds for axis 0 with size 1877
Traceback (most recent call last):
  File "/oasis/projects/nsf/azs119/edisj/Comet/benchmarks/vanilla_stripe/scripts/24/benchmark.py", line 204, in <module>
    times_array, rmsd_array = benchmark(topology, trajectory)
  File "/oasis/projects/nsf/azs119/edisj/Comet/benchmarks/vanilla_stripe/scripts/24/benchmark.py", line 58, in benchmark
    rmsd_array[i] = rmsd(CA.positions, x_ref, superposition=True)
IndexError: index 1877 is out of bounds for axis 0 with size 1877
Traceback (most recent call last):
  File "/oasis/projects/nsf/azs119/edisj/Comet/benchmarks/vanilla_stripe/scripts/24/benchmark.py", line 204, in <module>
    times_array, rmsd_array = benchmark(topology, trajectory)
  File "/oasis/projects/nsf/azs119/edisj/Comet/benchmarks/vanilla_stripe/scripts/24/benchmark.py", line 58, in benchmark
    rmsd_array[i] = rmsd(CA.positions, x_ref, superposition=True)
IndexError: index 1877 is out of bounds for axis 0 with size 1877
Traceback (most recent call last):
  File "/oasis/projects/nsf/azs119/edisj/Comet/benchmarks/vanilla_stripe/scripts/24/benchmark.py", line 204, in <module>
    times_array, rmsd_array = benchmark(topology, trajectory)
  File "/oasis/projects/nsf/azs119/edisj/Comet/benchmarks/vanilla_stripe/scripts/24/benchmark.py", line 58, in benchmark
    rmsd_array[i] = rmsd(CA.positions, x_ref, superposition=True)
IndexError: index 1877 is out of bounds for axis 0 with size 1877
Traceback (most recent call last):
  File "/oasis/projects/nsf/azs119/edisj/Comet/benchmarks/vanilla_stripe/scripts/24/benchmark.py", line 204, in <module>
    times_array, rmsd_array = benchmark(topology, trajectory)
  File "/oasis/projects/nsf/azs119/edisj/Comet/benchmarks/vanilla_stripe/scripts/24/benchmark.py", line 58, in benchmark
    rmsd_array[i] = rmsd(CA.positions, x_ref, superposition=True)
IndexError: index 1877 is out of bounds for axis 0 with size 1877
Traceback (most recent call last):
  File "/oasis/projects/nsf/azs119/edisj/Comet/benchmarks/vanilla_stripe/scripts/24/benchmark.py", line 204, in <module>
    times_array, rmsd_array = benchmark(topology, trajectory)
  File "/oasis/projects/nsf/azs119/edisj/Comet/benchmarks/vanilla_stripe/scripts/24/benchmark.py", line 58, in benchmark
    rmsd_array[i] = rmsd(CA.positions, x_ref, superposition=True)
IndexError: index 1877 is out of bounds for axis 0 with size 1877
Traceback (most recent call last):
  File "/oasis/projects/nsf/azs119/edisj/Comet/benchmarks/vanilla_stripe/scripts/24/benchmark.py", line 204, in <module>
    times_array, rmsd_array = benchmark(topology, trajectory)
  File "/oasis/projects/nsf/azs119/edisj/Comet/benchmarks/vanilla_stripe/scripts/24/benchmark.py", line 58, in benchmark
    rmsd_array[i] = rmsd(CA.positions, x_ref, superposition=True)
IndexError: index 1877 is out of bounds for axis 0 with size 1877
Traceback (most recent call last):
  File "/oasis/projects/nsf/azs119/edisj/Comet/benchmarks/vanilla_stripe/scripts/24/benchmark.py", line 204, in <module>
    times_array, rmsd_array = benchmark(topology, trajectory)
  File "/oasis/projects/nsf/azs119/edisj/Comet/benchmarks/vanilla_stripe/scripts/24/benchmark.py", line 58, in benchmark
    rmsd_array[i] = rmsd(CA.positions, x_ref, superposition=True)
IndexError: index 1877 is out of bounds for axis 0 with size 1877
Traceback (most recent call last):
  File "/oasis/projects/nsf/azs119/edisj/Comet/benchmarks/vanilla_stripe/scripts/24/benchmark.py", line 204, in <module>
    times_array, rmsd_array = benchmark(topology, trajectory)
  File "/oasis/projects/nsf/azs119/edisj/Comet/benchmarks/vanilla_stripe/scripts/24/benchmark.py", line 58, in benchmark
    rmsd_array[i] = rmsd(CA.positions, x_ref, superposition=True)
IndexError: index 1877 is out of bounds for axis 0 with size 1877
Traceback (most recent call last):
  File "/oasis/projects/nsf/azs119/edisj/Comet/benchmarks/vanilla_stripe/scripts/24/benchmark.py", line 204, in <module>
    times_array, rmsd_array = benchmark(topology, trajectory)
  File "/oasis/projects/nsf/azs119/edisj/Comet/benchmarks/vanilla_stripe/scripts/24/benchmark.py", line 58, in benchmark
    rmsd_array[i] = rmsd(CA.positions, x_ref, superposition=True)
IndexError: index 1877 is out of bounds for axis 0 with size 1877
Traceback (most recent call last):
  File "/oasis/projects/nsf/azs119/edisj/Comet/benchmarks/vanilla_stripe/scripts/24/benchmark.py", line 204, in <module>
    times_array, rmsd_array = benchmark(topology, trajectory)
  File "/oasis/projects/nsf/azs119/edisj/Comet/benchmarks/vanilla_stripe/scripts/24/benchmark.py", line 58, in benchmark
    rmsd_array[i] = rmsd(CA.positions, x_ref, superposition=True)
IndexError: index 1877 is out of bounds for axis 0 with size 1877
Traceback (most recent call last):
  File "/oasis/projects/nsf/azs119/edisj/Comet/benchmarks/vanilla_stripe/scripts/24/benchmark.py", line 204, in <module>
    times_array, rmsd_array = benchmark(topology, trajectory)
  File "/oasis/projects/nsf/azs119/edisj/Comet/benchmarks/vanilla_stripe/scripts/24/benchmark.py", line 58, in benchmark
    rmsd_array[i] = rmsd(CA.positions, x_ref, superposition=True)
IndexError: index 1877 is out of bounds for axis 0 with size 1877
Traceback (most recent call last):
  File "/oasis/projects/nsf/azs119/edisj/Comet/benchmarks/vanilla_stripe/scripts/24/benchmark.py", line 204, in <module>
    times_array, rmsd_array = benchmark(topology, trajectory)
  File "/oasis/projects/nsf/azs119/edisj/Comet/benchmarks/vanilla_stripe/scripts/24/benchmark.py", line 58, in benchmark
    rmsd_array[i] = rmsd(CA.positions, x_ref, superposition=True)
IndexError: index 1877 is out of bounds for axis 0 with size 1877
Traceback (most recent call last):
  File "/oasis/projects/nsf/azs119/edisj/Comet/benchmarks/vanilla_stripe/scripts/24/benchmark.py", line 204, in <module>
    times_array, rmsd_array = benchmark(topology, trajectory)
  File "/oasis/projects/nsf/azs119/edisj/Comet/benchmarks/vanilla_stripe/scripts/24/benchmark.py", line 58, in benchmark
    rmsd_array[i] = rmsd(CA.positions, x_ref, superposition=True)
IndexError: index 1877 is out of bounds for axis 0 with size 1877
Traceback (most recent call last):
  File "/oasis/projects/nsf/azs119/edisj/Comet/benchmarks/vanilla_stripe/scripts/24/benchmark.py", line 204, in <module>
    times_array, rmsd_array = benchmark(topology, trajectory)
  File "/oasis/projects/nsf/azs119/edisj/Comet/benchmarks/vanilla_stripe/scripts/24/benchmark.py", line 58, in benchmark
    rmsd_array[i] = rmsd(CA.positions, x_ref, superposition=True)
IndexError: index 1877 is out of bounds for axis 0 with size 1877
Traceback (most recent call last):
  File "/oasis/projects/nsf/azs119/edisj/Comet/benchmarks/vanilla_stripe/scripts/24/benchmark.py", line 204, in <module>
    times_array, rmsd_array = benchmark(topology, trajectory)
  File "/oasis/projects/nsf/azs119/edisj/Comet/benchmarks/vanilla_stripe/scripts/24/benchmark.py", line 58, in benchmark
    rmsd_array[i] = rmsd(CA.positions, x_ref, superposition=True)
IndexError: index 1877 is out of bounds for axis 0 with size 1877
Traceback (most recent call last):
  File "/oasis/projects/nsf/azs119/edisj/Comet/benchmarks/vanilla_stripe/scripts/24/benchmark.py", line 204, in <module>
    times_array, rmsd_array = benchmark(topology, trajectory)
  File "/oasis/projects/nsf/azs119/edisj/Comet/benchmarks/vanilla_stripe/scripts/24/benchmark.py", line 58, in benchmark
    rmsd_array[i] = rmsd(CA.positions, x_ref, superposition=True)
IndexError: index 1877 is out of bounds for axis 0 with size 1877
Traceback (most recent call last):
  File "/oasis/projects/nsf/azs119/edisj/Comet/benchmarks/vanilla_stripe/scripts/24/benchmark.py", line 204, in <module>
    times_array, rmsd_array = benchmark(topology, trajectory)
  File "/oasis/projects/nsf/azs119/edisj/Comet/benchmarks/vanilla_stripe/scripts/24/benchmark.py", line 58, in benchmark
    rmsd_array[i] = rmsd(CA.positions, x_ref, superposition=True)
IndexError: index 1877 is out of bounds for axis 0 with size 1877
Traceback (most recent call last):
  File "/oasis/projects/nsf/azs119/edisj/Comet/benchmarks/vanilla_stripe/scripts/24/benchmark.py", line 204, in <module>
    times_array, rmsd_array = benchmark(topology, trajectory)
  File "/oasis/projects/nsf/azs119/edisj/Comet/benchmarks/vanilla_stripe/scripts/24/benchmark.py", line 58, in benchmark
    rmsd_array[i] = rmsd(CA.positions, x_ref, superposition=True)
IndexError: index 1877 is out of bounds for axis 0 with size 1877
Traceback (most recent call last):
  File "/oasis/projects/nsf/azs119/edisj/Comet/benchmarks/vanilla_stripe/scripts/24/benchmark.py", line 204, in <module>
    times_array, rmsd_array = benchmark(topology, trajectory)
  File "/oasis/projects/nsf/azs119/edisj/Comet/benchmarks/vanilla_stripe/scripts/24/benchmark.py", line 58, in benchmark
    rmsd_array[i] = rmsd(CA.positions, x_ref, superposition=True)
IndexError: index 1877 is out of bounds for axis 0 with size 1877
Exception ignored in: <object repr() failed>
Traceback (most recent call last):
  File "/home/edisj/mdanalysis/package/MDAnalysis/coordinates/base.py", line 2165, in __del__
  File "/home/edisj/mdanalysis/package/MDAnalysis/coordinates/H5MD.py", line 978, in close
  File "/home/edisj/anaconda3/envs/mda8/lib/python3.6/site-packages/h5py/_hl/files.py", line 445, in close
  File "h5py/_objects.pyx", line 54, in h5py._objects.with_phil.wrapper
  File "h5py/_objects.pyx", line 55, in h5py._objects.with_phil.wrapper
  File "h5py/h5f.pyx", line 275, in h5py.h5f.get_obj_ids
  File "h5py/h5i.pyx", line 46, in h5py.h5i.wrap_identifier
ImportError: sys.meta_path is None, Python is likely shutting down
Traceback (most recent call last):
  File "h5py/_objects.pyx", line 199, in h5py._objects.ObjectID.__dealloc__
RuntimeError: Can't decrement id ref count (can't close file, there are objects still open)
Exception ignored in: 'h5py._objects.ObjectID.__dealloc__'
Traceback (most recent call last):
  File "h5py/_objects.pyx", line 199, in h5py._objects.ObjectID.__dealloc__
RuntimeError: Can't decrement id ref count (can't close file, there are objects still open)
Exception ignored in: <object repr() failed>
Traceback (most recent call last):
  File "/home/edisj/mdanalysis/package/MDAnalysis/coordinates/base.py", line 2165, in __del__
  File "/home/edisj/mdanalysis/package/MDAnalysis/coordinates/H5MD.py", line 978, in close
  File "/home/edisj/anaconda3/envs/mda8/lib/python3.6/site-packages/h5py/_hl/files.py", line 445, in close
  File "h5py/_objects.pyx", line 54, in h5py._objects.with_phil.wrapper
  File "h5py/_objects.pyx", line 55, in h5py._objects.with_phil.wrapper
  File "h5py/h5f.pyx", line 275, in h5py.h5f.get_obj_ids
  File "h5py/h5i.pyx", line 46, in h5py.h5i.wrap_identifier
ImportError: sys.meta_path is None, Python is likely shutting down
Traceback (most recent call last):
  File "h5py/_objects.pyx", line 199, in h5py._objects.ObjectID.__dealloc__
RuntimeError: Can't decrement id ref count (can't close file, there are objects still open)
Exception ignored in: 'h5py._objects.ObjectID.__dealloc__'
Traceback (most recent call last):
  File "h5py/_objects.pyx", line 199, in h5py._objects.ObjectID.__dealloc__
RuntimeError: Can't decrement id ref count (can't close file, there are objects still open)
Exception ignored in: <object repr() failed>
Traceback (most recent call last):
  File "/home/edisj/mdanalysis/package/MDAnalysis/coordinates/base.py", line 2165, in __del__
  File "/home/edisj/mdanalysis/package/MDAnalysis/coordinates/H5MD.py", line 978, in close
  File "/home/edisj/anaconda3/envs/mda8/lib/python3.6/site-packages/h5py/_hl/files.py", line 445, in close
  File "h5py/_objects.pyx", line 54, in h5py._objects.with_phil.wrapper
  File "h5py/_objects.pyx", line 55, in h5py._objects.with_phil.wrapper
  File "h5py/h5f.pyx", line 275, in h5py.h5f.get_obj_ids
  File "h5py/h5i.pyx", line 46, in h5py.h5i.wrap_identifier
ImportError: sys.meta_path is None, Python is likely shutting down
Traceback (most recent call last):
  File "h5py/_objects.pyx", line 199, in h5py._objects.ObjectID.__dealloc__
RuntimeError: Can't decrement id ref count (can't close file, there are objects still open)
Exception ignored in: 'h5py._objects.ObjectID.__dealloc__'
Traceback (most recent call last):
  File "h5py/_objects.pyx", line 199, in h5py._objects.ObjectID.__dealloc__
RuntimeError: Can't decrement id ref count (can't close file, there are objects still open)
Exception ignored in: <object repr() failed>
Traceback (most recent call last):
  File "/home/edisj/mdanalysis/package/MDAnalysis/coordinates/base.py", line 2165, in __del__
  File "/home/edisj/mdanalysis/package/MDAnalysis/coordinates/H5MD.py", line 978, in close
  File "/home/edisj/anaconda3/envs/mda8/lib/python3.6/site-packages/h5py/_hl/files.py", line 445, in close
  File "h5py/_objects.pyx", line 54, in h5py._objects.with_phil.wrapper
  File "h5py/_objects.pyx", line 55, in h5py._objects.with_phil.wrapper
  File "h5py/h5f.pyx", line 275, in h5py.h5f.get_obj_ids
  File "h5py/h5i.pyx", line 46, in h5py.h5i.wrap_identifier
ImportError: sys.meta_path is None, Python is likely shutting down
Traceback (most recent call last):
  File "h5py/_objects.pyx", line 199, in h5py._objects.ObjectID.__dealloc__
RuntimeError: Can't decrement id ref count (can't close file, there are objects still open)
Exception ignored in: 'h5py._objects.ObjectID.__dealloc__'
Traceback (most recent call last):
  File "h5py/_objects.pyx", line 199, in h5py._objects.ObjectID.__dealloc__
RuntimeError: Can't decrement id ref count (can't close file, there are objects still open)
Exception ignored in: <object repr() failed>
Traceback (most recent call last):
  File "/home/edisj/mdanalysis/package/MDAnalysis/coordinates/base.py", line 2165, in __del__
  File "/home/edisj/mdanalysis/package/MDAnalysis/coordinates/H5MD.py", line 978, in close
  File "/home/edisj/anaconda3/envs/mda8/lib/python3.6/site-packages/h5py/_hl/files.py", line 445, in close
  File "h5py/_objects.pyx", line 54, in h5py._objects.with_phil.wrapper
  File "h5py/_objects.pyx", line 55, in h5py._objects.with_phil.wrapper
  File "h5py/h5f.pyx", line 275, in h5py.h5f.get_obj_ids
  File "h5py/h5i.pyx", line 46, in h5py.h5i.wrap_identifier
ImportError: sys.meta_path is None, Python is likely shutting down
Traceback (most recent call last):
  File "h5py/_objects.pyx", line 199, in h5py._objects.ObjectID.__dealloc__
RuntimeError: Can't decrement id ref count (can't close file, there are objects still open)
Exception ignored in: 'h5py._objects.ObjectID.__dealloc__'
Traceback (most recent call last):
  File "h5py/_objects.pyx", line 199, in h5py._objects.ObjectID.__dealloc__
RuntimeError: Can't decrement id ref count (can't close file, there are objects still open)
Exception ignored in: <object repr() failed>
Traceback (most recent call last):
  File "/home/edisj/mdanalysis/package/MDAnalysis/coordinates/base.py", line 2165, in __del__
  File "/home/edisj/mdanalysis/package/MDAnalysis/coordinates/H5MD.py", line 978, in close
  File "/home/edisj/anaconda3/envs/mda8/lib/python3.6/site-packages/h5py/_hl/files.py", line 445, in close
  File "h5py/_objects.pyx", line 54, in h5py._objects.with_phil.wrapper
  File "h5py/_objects.pyx", line 55, in h5py._objects.with_phil.wrapper
  File "h5py/h5f.pyx", line 275, in h5py.h5f.get_obj_ids
  File "h5py/h5i.pyx", line 46, in h5py.h5i.wrap_identifier
ImportError: sys.meta_path is None, Python is likely shutting down
Traceback (most recent call last):
  File "h5py/_objects.pyx", line 199, in h5py._objects.ObjectID.__dealloc__
RuntimeError: Can't decrement id ref count (can't close file, there are objects still open)
Exception ignored in: 'h5py._objects.ObjectID.__dealloc__'
Traceback (most recent call last):
  File "h5py/_objects.pyx", line 199, in h5py._objects.ObjectID.__dealloc__
RuntimeError: Can't decrement id ref count (can't close file, there are objects still open)
Exception ignored in: <object repr() failed>
Traceback (most recent call last):
  File "/home/edisj/mdanalysis/package/MDAnalysis/coordinates/base.py", line 2165, in __del__
  File "/home/edisj/mdanalysis/package/MDAnalysis/coordinates/H5MD.py", line 978, in close
  File "/home/edisj/anaconda3/envs/mda8/lib/python3.6/site-packages/h5py/_hl/files.py", line 445, in close
  File "h5py/_objects.pyx", line 54, in h5py._objects.with_phil.wrapper
  File "h5py/_objects.pyx", line 55, in h5py._objects.with_phil.wrapper
  File "h5py/h5f.pyx", line 275, in h5py.h5f.get_obj_ids
  File "h5py/h5i.pyx", line 46, in h5py.h5i.wrap_identifier
ImportError: sys.meta_path is None, Python is likely shutting down
Traceback (most recent call last):
  File "h5py/_objects.pyx", line 199, in h5py._objects.ObjectID.__dealloc__
RuntimeError: Can't decrement id ref count (can't close file, there are objects still open)
Exception ignored in: 'h5py._objects.ObjectID.__dealloc__'
Traceback (most recent call last):
  File "h5py/_objects.pyx", line 199, in h5py._objects.ObjectID.__dealloc__
RuntimeError: Can't decrement id ref count (can't close file, there are objects still open)
Exception ignored in: <object repr() failed>
Traceback (most recent call last):
  File "/home/edisj/mdanalysis/package/MDAnalysis/coordinates/base.py", line 2165, in __del__
  File "/home/edisj/mdanalysis/package/MDAnalysis/coordinates/H5MD.py", line 978, in close
  File "/home/edisj/anaconda3/envs/mda8/lib/python3.6/site-packages/h5py/_hl/files.py", line 445, in close
  File "h5py/_objects.pyx", line 54, in h5py._objects.with_phil.wrapper
  File "h5py/_objects.pyx", line 55, in h5py._objects.with_phil.wrapper
  File "h5py/h5f.pyx", line 275, in h5py.h5f.get_obj_ids
  File "h5py/h5i.pyx", line 46, in h5py.h5i.wrap_identifier
ImportError: sys.meta_path is None, Python is likely shutting down
Traceback (most recent call last):
  File "h5py/_objects.pyx", line 199, in h5py._objects.ObjectID.__dealloc__
RuntimeError: Can't decrement id ref count (can't close file, there are objects still open)
Exception ignored in: 'h5py._objects.ObjectID.__dealloc__'
Traceback (most recent call last):
  File "h5py/_objects.pyx", line 199, in h5py._objects.ObjectID.__dealloc__
RuntimeError: Can't decrement id ref count (can't close file, there are objects still open)
Exception ignored in: <object repr() failed>
Traceback (most recent call last):
  File "/home/edisj/mdanalysis/package/MDAnalysis/coordinates/base.py", line 2165, in __del__
  File "/home/edisj/mdanalysis/package/MDAnalysis/coordinates/H5MD.py", line 978, in close
  File "/home/edisj/anaconda3/envs/mda8/lib/python3.6/site-packages/h5py/_hl/files.py", line 445, in close
  File "h5py/_objects.pyx", line 54, in h5py._objects.with_phil.wrapper
  File "h5py/_objects.pyx", line 55, in h5py._objects.with_phil.wrapper
  File "h5py/h5f.pyx", line 275, in h5py.h5f.get_obj_ids
  File "h5py/h5i.pyx", line 46, in h5py.h5i.wrap_identifier
ImportError: sys.meta_path is None, Python is likely shutting down
Traceback (most recent call last):
  File "h5py/_objects.pyx", line 199, in h5py._objects.ObjectID.__dealloc__
RuntimeError: Can't decrement id ref count (can't close file, there are objects still open)
Exception ignored in: 'h5py._objects.ObjectID.__dealloc__'
Traceback (most recent call last):
  File "h5py/_objects.pyx", line 199, in h5py._objects.ObjectID.__dealloc__
RuntimeError: Can't decrement id ref count (can't close file, there are objects still open)
Exception ignored in: <object repr() failed>
Traceback (most recent call last):
  File "/home/edisj/mdanalysis/package/MDAnalysis/coordinates/base.py", line 2165, in __del__
  File "/home/edisj/mdanalysis/package/MDAnalysis/coordinates/H5MD.py", line 978, in close
  File "/home/edisj/anaconda3/envs/mda8/lib/python3.6/site-packages/h5py/_hl/files.py", line 445, in close
  File "h5py/_objects.pyx", line 54, in h5py._objects.with_phil.wrapper
  File "h5py/_objects.pyx", line 55, in h5py._objects.with_phil.wrapper
  File "h5py/h5f.pyx", line 275, in h5py.h5f.get_obj_ids
  File "h5py/h5i.pyx", line 46, in h5py.h5i.wrap_identifier
ImportError: sys.meta_path is None, Python is likely shutting down
Traceback (most recent call last):
  File "h5py/_objects.pyx", line 199, in h5py._objects.ObjectID.__dealloc__
RuntimeError: Can't decrement id ref count (can't close file, there are objects still open)
Exception ignored in: 'h5py._objects.ObjectID.__dealloc__'
Traceback (most recent call last):
  File "h5py/_objects.pyx", line 199, in h5py._objects.ObjectID.__dealloc__
RuntimeError: Can't decrement id ref count (can't close file, there are objects still open)
Exception ignored in: <object repr() failed>
Traceback (most recent call last):
  File "/home/edisj/mdanalysis/package/MDAnalysis/coordinates/base.py", line 2165, in __del__
  File "/home/edisj/mdanalysis/package/MDAnalysis/coordinates/H5MD.py", line 978, in close
  File "/home/edisj/anaconda3/envs/mda8/lib/python3.6/site-packages/h5py/_hl/files.py", line 445, in close
  File "h5py/_objects.pyx", line 54, in h5py._objects.with_phil.wrapper
  File "h5py/_objects.pyx", line 55, in h5py._objects.with_phil.wrapper
  File "h5py/h5f.pyx", line 275, in h5py.h5f.get_obj_ids
  File "h5py/h5i.pyx", line 46, in h5py.h5i.wrap_identifier
ImportError: sys.meta_path is None, Python is likely shutting down
Traceback (most recent call last):
  File "h5py/_objects.pyx", line 199, in h5py._objects.ObjectID.__dealloc__
RuntimeError: Can't decrement id ref count (can't close file, there are objects still open)
Exception ignored in: 'h5py._objects.ObjectID.__dealloc__'
Traceback (most recent call last):
  File "h5py/_objects.pyx", line 199, in h5py._objects.ObjectID.__dealloc__
RuntimeError: Can't decrement id ref count (can't close file, there are objects still open)
Exception ignored in: <object repr() failed>
Traceback (most recent call last):
  File "/home/edisj/mdanalysis/package/MDAnalysis/coordinates/base.py", line 2165, in __del__
  File "/home/edisj/mdanalysis/package/MDAnalysis/coordinates/H5MD.py", line 978, in close
  File "/home/edisj/anaconda3/envs/mda8/lib/python3.6/site-packages/h5py/_hl/files.py", line 445, in close
  File "h5py/_objects.pyx", line 54, in h5py._objects.with_phil.wrapper
  File "h5py/_objects.pyx", line 55, in h5py._objects.with_phil.wrapper
  File "h5py/h5f.pyx", line 275, in h5py.h5f.get_obj_ids
  File "h5py/h5i.pyx", line 46, in h5py.h5i.wrap_identifier
ImportError: sys.meta_path is None, Python is likely shutting down
Traceback (most recent call last):
  File "h5py/_objects.pyx", line 199, in h5py._objects.ObjectID.__dealloc__
RuntimeError: Can't decrement id ref count (can't close file, there are objects still open)
Exception ignored in: 'h5py._objects.ObjectID.__dealloc__'
Traceback (most recent call last):
  File "h5py/_objects.pyx", line 199, in h5py._objects.ObjectID.__dealloc__
RuntimeError: Can't decrement id ref count (can't close file, there are objects still open)
Exception ignored in: <object repr() failed>
Traceback (most recent call last):
  File "/home/edisj/mdanalysis/package/MDAnalysis/coordinates/base.py", line 2165, in __del__
  File "/home/edisj/mdanalysis/package/MDAnalysis/coordinates/H5MD.py", line 978, in close
  File "/home/edisj/anaconda3/envs/mda8/lib/python3.6/site-packages/h5py/_hl/files.py", line 445, in close
  File "h5py/_objects.pyx", line 54, in h5py._objects.with_phil.wrapper
  File "h5py/_objects.pyx", line 55, in h5py._objects.with_phil.wrapper
  File "h5py/h5f.pyx", line 275, in h5py.h5f.get_obj_ids
  File "h5py/h5i.pyx", line 46, in h5py.h5i.wrap_identifier
ImportError: sys.meta_path is None, Python is likely shutting down
Traceback (most recent call last):
  File "h5py/_objects.pyx", line 199, in h5py._objects.ObjectID.__dealloc__
RuntimeError: Can't decrement id ref count (can't close file, there are objects still open)
Exception ignored in: 'h5py._objects.ObjectID.__dealloc__'
Traceback (most recent call last):
  File "h5py/_objects.pyx", line 199, in h5py._objects.ObjectID.__dealloc__
RuntimeError: Can't decrement id ref count (can't close file, there are objects still open)
Exception ignored in: <object repr() failed>
Traceback (most recent call last):
  File "/home/edisj/mdanalysis/package/MDAnalysis/coordinates/base.py", line 2165, in __del__
  File "/home/edisj/mdanalysis/package/MDAnalysis/coordinates/H5MD.py", line 978, in close
  File "/home/edisj/anaconda3/envs/mda8/lib/python3.6/site-packages/h5py/_hl/files.py", line 445, in close
  File "h5py/_objects.pyx", line 54, in h5py._objects.with_phil.wrapper
  File "h5py/_objects.pyx", line 55, in h5py._objects.with_phil.wrapper
  File "h5py/h5f.pyx", line 275, in h5py.h5f.get_obj_ids
  File "h5py/h5i.pyx", line 46, in h5py.h5i.wrap_identifier
ImportError: sys.meta_path is None, Python is likely shutting down
Traceback (most recent call last):
  File "h5py/_objects.pyx", line 199, in h5py._objects.ObjectID.__dealloc__
RuntimeError: Can't decrement id ref count (can't close file, there are objects still open)
Exception ignored in: 'h5py._objects.ObjectID.__dealloc__'
Traceback (most recent call last):
  File "h5py/_objects.pyx", line 199, in h5py._objects.ObjectID.__dealloc__
RuntimeError: Can't decrement id ref count (can't close file, there are objects still open)
Exception ignored in: <object repr() failed>
Traceback (most recent call last):
  File "/home/edisj/mdanalysis/package/MDAnalysis/coordinates/base.py", line 2165, in __del__
  File "/home/edisj/mdanalysis/package/MDAnalysis/coordinates/H5MD.py", line 978, in close
  File "/home/edisj/anaconda3/envs/mda8/lib/python3.6/site-packages/h5py/_hl/files.py", line 445, in close
  File "h5py/_objects.pyx", line 54, in h5py._objects.with_phil.wrapper
  File "h5py/_objects.pyx", line 55, in h5py._objects.with_phil.wrapper
  File "h5py/h5f.pyx", line 275, in h5py.h5f.get_obj_ids
  File "h5py/h5i.pyx", line 46, in h5py.h5i.wrap_identifier
ImportError: sys.meta_path is None, Python is likely shutting down
Traceback (most recent call last):
  File "h5py/_objects.pyx", line 199, in h5py._objects.ObjectID.__dealloc__
RuntimeError: Can't decrement id ref count (can't close file, there are objects still open)
Exception ignored in: 'h5py._objects.ObjectID.__dealloc__'
Traceback (most recent call last):
  File "h5py/_objects.pyx", line 199, in h5py._objects.ObjectID.__dealloc__
RuntimeError: Can't decrement id ref count (can't close file, there are objects still open)
Exception ignored in: <object repr() failed>
Traceback (most recent call last):
  File "/home/edisj/mdanalysis/package/MDAnalysis/coordinates/base.py", line 2165, in __del__
  File "/home/edisj/mdanalysis/package/MDAnalysis/coordinates/H5MD.py", line 978, in close
  File "/home/edisj/anaconda3/envs/mda8/lib/python3.6/site-packages/h5py/_hl/files.py", line 445, in close
  File "h5py/_objects.pyx", line 54, in h5py._objects.with_phil.wrapper
  File "h5py/_objects.pyx", line 55, in h5py._objects.with_phil.wrapper
  File "h5py/h5f.pyx", line 275, in h5py.h5f.get_obj_ids
  File "h5py/h5i.pyx", line 46, in h5py.h5i.wrap_identifier
ImportError: sys.meta_path is None, Python is likely shutting down
Traceback (most recent call last):
  File "h5py/_objects.pyx", line 199, in h5py._objects.ObjectID.__dealloc__
RuntimeError: Can't decrement id ref count (can't close file, there are objects still open)
Exception ignored in: 'h5py._objects.ObjectID.__dealloc__'
Traceback (most recent call last):
  File "h5py/_objects.pyx", line 199, in h5py._objects.ObjectID.__dealloc__
RuntimeError: Can't decrement id ref count (can't close file, there are objects still open)
Exception ignored in: <object repr() failed>
Traceback (most recent call last):
  File "/home/edisj/mdanalysis/package/MDAnalysis/coordinates/base.py", line 2165, in __del__
  File "/home/edisj/mdanalysis/package/MDAnalysis/coordinates/H5MD.py", line 978, in close
  File "/home/edisj/anaconda3/envs/mda8/lib/python3.6/site-packages/h5py/_hl/files.py", line 445, in close
  File "h5py/_objects.pyx", line 54, in h5py._objects.with_phil.wrapper
  File "h5py/_objects.pyx", line 55, in h5py._objects.with_phil.wrapper
  File "h5py/h5f.pyx", line 275, in h5py.h5f.get_obj_ids
  File "h5py/h5i.pyx", line 46, in h5py.h5i.wrap_identifier
ImportError: sys.meta_path is None, Python is likely shutting down
Traceback (most recent call last):
  File "h5py/_objects.pyx", line 199, in h5py._objects.ObjectID.__dealloc__
RuntimeError: Can't decrement id ref count (can't close file, there are objects still open)
Exception ignored in: 'h5py._objects.ObjectID.__dealloc__'
Traceback (most recent call last):
  File "h5py/_objects.pyx", line 199, in h5py._objects.ObjectID.__dealloc__
RuntimeError: Can't decrement id ref count (can't close file, there are objects still open)
Exception ignored in: <object repr() failed>
Traceback (most recent call last):
  File "/home/edisj/mdanalysis/package/MDAnalysis/coordinates/base.py", line 2165, in __del__
  File "/home/edisj/mdanalysis/package/MDAnalysis/coordinates/H5MD.py", line 978, in close
  File "/home/edisj/anaconda3/envs/mda8/lib/python3.6/site-packages/h5py/_hl/files.py", line 445, in close
  File "h5py/_objects.pyx", line 54, in h5py._objects.with_phil.wrapper
  File "h5py/_objects.pyx", line 55, in h5py._objects.with_phil.wrapper
  File "h5py/h5f.pyx", line 275, in h5py.h5f.get_obj_ids
  File "h5py/h5i.pyx", line 46, in h5py.h5i.wrap_identifier
ImportError: sys.meta_path is None, Python is likely shutting down
Traceback (most recent call last):
  File "h5py/_objects.pyx", line 199, in h5py._objects.ObjectID.__dealloc__
RuntimeError: Can't decrement id ref count (can't close file, there are objects still open)
Exception ignored in: 'h5py._objects.ObjectID.__dealloc__'
Traceback (most recent call last):
  File "h5py/_objects.pyx", line 199, in h5py._objects.ObjectID.__dealloc__
RuntimeError: Can't decrement id ref count (can't close file, there are objects still open)
Exception ignored in: <object repr() failed>
Traceback (most recent call last):
  File "/home/edisj/mdanalysis/package/MDAnalysis/coordinates/base.py", line 2165, in __del__
  File "/home/edisj/mdanalysis/package/MDAnalysis/coordinates/H5MD.py", line 978, in close
  File "/home/edisj/anaconda3/envs/mda8/lib/python3.6/site-packages/h5py/_hl/files.py", line 445, in close
  File "h5py/_objects.pyx", line 54, in h5py._objects.with_phil.wrapper
  File "h5py/_objects.pyx", line 55, in h5py._objects.with_phil.wrapper
  File "h5py/h5f.pyx", line 275, in h5py.h5f.get_obj_ids
  File "h5py/h5i.pyx", line 46, in h5py.h5i.wrap_identifier
ImportError: sys.meta_path is None, Python is likely shutting down
Traceback (most recent call last):
  File "h5py/_objects.pyx", line 199, in h5py._objects.ObjectID.__dealloc__
RuntimeError: Can't decrement id ref count (can't close file, there are objects still open)
Exception ignored in: 'h5py._objects.ObjectID.__dealloc__'
Traceback (most recent call last):
  File "h5py/_objects.pyx", line 199, in h5py._objects.ObjectID.__dealloc__
RuntimeError: Can't decrement id ref count (can't close file, there are objects still open)
Exception ignored in: <object repr() failed>
Traceback (most recent call last):
  File "/home/edisj/mdanalysis/package/MDAnalysis/coordinates/base.py", line 2165, in __del__
  File "/home/edisj/mdanalysis/package/MDAnalysis/coordinates/H5MD.py", line 978, in close
  File "/home/edisj/anaconda3/envs/mda8/lib/python3.6/site-packages/h5py/_hl/files.py", line 445, in close
  File "h5py/_objects.pyx", line 54, in h5py._objects.with_phil.wrapper
  File "h5py/_objects.pyx", line 55, in h5py._objects.with_phil.wrapper
  File "h5py/h5f.pyx", line 275, in h5py.h5f.get_obj_ids
  File "h5py/h5i.pyx", line 46, in h5py.h5i.wrap_identifier
ImportError: sys.meta_path is None, Python is likely shutting down
Traceback (most recent call last):
  File "h5py/_objects.pyx", line 199, in h5py._objects.ObjectID.__dealloc__
RuntimeError: Can't decrement id ref count (can't close file, there are objects still open)
Exception ignored in: 'h5py._objects.ObjectID.__dealloc__'
Traceback (most recent call last):
  File "h5py/_objects.pyx", line 199, in h5py._objects.ObjectID.__dealloc__
RuntimeError: Can't decrement id ref count (can't close file, there are objects still open)
Exception ignored in: <object repr() failed>
Traceback (most recent call last):
  File "/home/edisj/mdanalysis/package/MDAnalysis/coordinates/base.py", line 2165, in __del__
  File "/home/edisj/mdanalysis/package/MDAnalysis/coordinates/H5MD.py", line 978, in close
  File "/home/edisj/anaconda3/envs/mda8/lib/python3.6/site-packages/h5py/_hl/files.py", line 445, in close
  File "h5py/_objects.pyx", line 54, in h5py._objects.with_phil.wrapper
  File "h5py/_objects.pyx", line 55, in h5py._objects.with_phil.wrapper
  File "h5py/h5f.pyx", line 275, in h5py.h5f.get_obj_ids
  File "h5py/h5i.pyx", line 46, in h5py.h5i.wrap_identifier
ImportError: sys.meta_path is None, Python is likely shutting down
Traceback (most recent call last):
  File "h5py/_objects.pyx", line 199, in h5py._objects.ObjectID.__dealloc__
RuntimeError: Can't decrement id ref count (can't close file, there are objects still open)
Exception ignored in: 'h5py._objects.ObjectID.__dealloc__'
Traceback (most recent call last):
  File "h5py/_objects.pyx", line 199, in h5py._objects.ObjectID.__dealloc__
RuntimeError: Can't decrement id ref count (can't close file, there are objects still open)
Exception ignored in: <object repr() failed>
Traceback (most recent call last):
  File "/home/edisj/mdanalysis/package/MDAnalysis/coordinates/base.py", line 2165, in __del__
  File "/home/edisj/mdanalysis/package/MDAnalysis/coordinates/H5MD.py", line 978, in close
  File "/home/edisj/anaconda3/envs/mda8/lib/python3.6/site-packages/h5py/_hl/files.py", line 445, in close
  File "h5py/_objects.pyx", line 54, in h5py._objects.with_phil.wrapper
  File "h5py/_objects.pyx", line 55, in h5py._objects.with_phil.wrapper
  File "h5py/h5f.pyx", line 275, in h5py.h5f.get_obj_ids
  File "h5py/h5i.pyx", line 46, in h5py.h5i.wrap_identifier
ImportError: sys.meta_path is None, Python is likely shutting down
Traceback (most recent call last):
  File "h5py/_objects.pyx", line 199, in h5py._objects.ObjectID.__dealloc__
RuntimeError: Can't decrement id ref count (can't close file, there are objects still open)
Exception ignored in: 'h5py._objects.ObjectID.__dealloc__'
Traceback (most recent call last):
  File "h5py/_objects.pyx", line 199, in h5py._objects.ObjectID.__dealloc__
RuntimeError: Can't decrement id ref count (can't close file, there are objects still open)
Exception ignored in: <object repr() failed>
Traceback (most recent call last):
  File "/home/edisj/mdanalysis/package/MDAnalysis/coordinates/base.py", line 2165, in __del__
  File "/home/edisj/mdanalysis/package/MDAnalysis/coordinates/H5MD.py", line 978, in close
  File "/home/edisj/anaconda3/envs/mda8/lib/python3.6/site-packages/h5py/_hl/files.py", line 445, in close
  File "h5py/_objects.pyx", line 54, in h5py._objects.with_phil.wrapper
  File "h5py/_objects.pyx", line 55, in h5py._objects.with_phil.wrapper
  File "h5py/h5f.pyx", line 275, in h5py.h5f.get_obj_ids
  File "h5py/h5i.pyx", line 46, in h5py.h5i.wrap_identifier
ImportError: sys.meta_path is None, Python is likely shutting down
Traceback (most recent call last):
  File "h5py/_objects.pyx", line 199, in h5py._objects.ObjectID.__dealloc__
RuntimeError: Can't decrement id ref count (can't close file, there are objects still open)
Exception ignored in: 'h5py._objects.ObjectID.__dealloc__'
Traceback (most recent call last):
  File "h5py/_objects.pyx", line 199, in h5py._objects.ObjectID.__dealloc__
RuntimeError: Can't decrement id ref count (can't close file, there are objects still open)
Exception ignored in: <object repr() failed>
Traceback (most recent call last):
  File "/home/edisj/mdanalysis/package/MDAnalysis/coordinates/base.py", line 2165, in __del__
  File "/home/edisj/mdanalysis/package/MDAnalysis/coordinates/H5MD.py", line 978, in close
  File "/home/edisj/anaconda3/envs/mda8/lib/python3.6/site-packages/h5py/_hl/files.py", line 445, in close
  File "h5py/_objects.pyx", line 54, in h5py._objects.with_phil.wrapper
  File "h5py/_objects.pyx", line 55, in h5py._objects.with_phil.wrapper
  File "h5py/h5f.pyx", line 275, in h5py.h5f.get_obj_ids
  File "h5py/h5i.pyx", line 46, in h5py.h5i.wrap_identifier
ImportError: sys.meta_path is None, Python is likely shutting down
Traceback (most recent call last):
  File "h5py/_objects.pyx", line 199, in h5py._objects.ObjectID.__dealloc__
RuntimeError: Can't decrement id ref count (can't close file, there are objects still open)
Exception ignored in: 'h5py._objects.ObjectID.__dealloc__'
Traceback (most recent call last):
  File "h5py/_objects.pyx", line 199, in h5py._objects.ObjectID.__dealloc__
RuntimeError: Can't decrement id ref count (can't close file, there are objects still open)
Traceback (most recent call last):
  File "/oasis/projects/nsf/azs119/edisj/Comet/benchmarks/vanilla_stripe/scripts/24/benchmark.py", line 204, in <module>
    times_array, rmsd_array = benchmark(topology, trajectory)
  File "/oasis/projects/nsf/azs119/edisj/Comet/benchmarks/vanilla_stripe/scripts/24/benchmark.py", line 58, in benchmark
    rmsd_array[i] = rmsd(CA.positions, x_ref, superposition=True)
IndexError: index 1877 is out of bounds for axis 0 with size 1877
Traceback (most recent call last):
  File "/oasis/projects/nsf/azs119/edisj/Comet/benchmarks/vanilla_stripe/scripts/24/benchmark.py", line 204, in <module>
    times_array, rmsd_array = benchmark(topology, trajectory)
  File "/oasis/projects/nsf/azs119/edisj/Comet/benchmarks/vanilla_stripe/scripts/24/benchmark.py", line 58, in benchmark
    rmsd_array[i] = rmsd(CA.positions, x_ref, superposition=True)
IndexError: index 1877 is out of bounds for axis 0 with size 1877
Traceback (most recent call last):
  File "/oasis/projects/nsf/azs119/edisj/Comet/benchmarks/vanilla_stripe/scripts/24/benchmark.py", line 204, in <module>
    times_array, rmsd_array = benchmark(topology, trajectory)
  File "/oasis/projects/nsf/azs119/edisj/Comet/benchmarks/vanilla_stripe/scripts/24/benchmark.py", line 58, in benchmark
    rmsd_array[i] = rmsd(CA.positions, x_ref, superposition=True)
IndexError: index 1877 is out of bounds for axis 0 with size 1877
Traceback (most recent call last):
  File "/oasis/projects/nsf/azs119/edisj/Comet/benchmarks/vanilla_stripe/scripts/24/benchmark.py", line 204, in <module>
    times_array, rmsd_array = benchmark(topology, trajectory)
  File "/oasis/projects/nsf/azs119/edisj/Comet/benchmarks/vanilla_stripe/scripts/24/benchmark.py", line 58, in benchmark
    rmsd_array[i] = rmsd(CA.positions, x_ref, superposition=True)
IndexError: index 1877 is out of bounds for axis 0 with size 1877
Traceback (most recent call last):
  File "/oasis/projects/nsf/azs119/edisj/Comet/benchmarks/vanilla_stripe/scripts/24/benchmark.py", line 204, in <module>
    times_array, rmsd_array = benchmark(topology, trajectory)
  File "/oasis/projects/nsf/azs119/edisj/Comet/benchmarks/vanilla_stripe/scripts/24/benchmark.py", line 58, in benchmark
    rmsd_array[i] = rmsd(CA.positions, x_ref, superposition=True)
IndexError: index 1877 is out of bounds for axis 0 with size 1877
Traceback (most recent call last):
  File "/oasis/projects/nsf/azs119/edisj/Comet/benchmarks/vanilla_stripe/scripts/24/benchmark.py", line 204, in <module>
    times_array, rmsd_array = benchmark(topology, trajectory)
  File "/oasis/projects/nsf/azs119/edisj/Comet/benchmarks/vanilla_stripe/scripts/24/benchmark.py", line 58, in benchmark
    rmsd_array[i] = rmsd(CA.positions, x_ref, superposition=True)
IndexError: index 1877 is out of bounds for axis 0 with size 1877
Traceback (most recent call last):
  File "/oasis/projects/nsf/azs119/edisj/Comet/benchmarks/vanilla_stripe/scripts/24/benchmark.py", line 204, in <module>
    times_array, rmsd_array = benchmark(topology, trajectory)
  File "/oasis/projects/nsf/azs119/edisj/Comet/benchmarks/vanilla_stripe/scripts/24/benchmark.py", line 58, in benchmark
    rmsd_array[i] = rmsd(CA.positions, x_ref, superposition=True)
IndexError: index 1877 is out of bounds for axis 0 with size 1877
Traceback (most recent call last):
  File "/oasis/projects/nsf/azs119/edisj/Comet/benchmarks/vanilla_stripe/scripts/24/benchmark.py", line 204, in <module>
    times_array, rmsd_array = benchmark(topology, trajectory)
  File "/oasis/projects/nsf/azs119/edisj/Comet/benchmarks/vanilla_stripe/scripts/24/benchmark.py", line 58, in benchmark
    rmsd_array[i] = rmsd(CA.positions, x_ref, superposition=True)
IndexError: index 1877 is out of bounds for axis 0 with size 1877
Traceback (most recent call last):
  File "/oasis/projects/nsf/azs119/edisj/Comet/benchmarks/vanilla_stripe/scripts/24/benchmark.py", line 204, in <module>
    times_array, rmsd_array = benchmark(topology, trajectory)
  File "/oasis/projects/nsf/azs119/edisj/Comet/benchmarks/vanilla_stripe/scripts/24/benchmark.py", line 58, in benchmark
    rmsd_array[i] = rmsd(CA.positions, x_ref, superposition=True)
IndexError: index 1877 is out of bounds for axis 0 with size 1877
Traceback (most recent call last):
  File "/oasis/projects/nsf/azs119/edisj/Comet/benchmarks/vanilla_stripe/scripts/24/benchmark.py", line 204, in <module>
    times_array, rmsd_array = benchmark(topology, trajectory)
  File "/oasis/projects/nsf/azs119/edisj/Comet/benchmarks/vanilla_stripe/scripts/24/benchmark.py", line 58, in benchmark
    rmsd_array[i] = rmsd(CA.positions, x_ref, superposition=True)
IndexError: index 1877 is out of bounds for axis 0 with size 1877
Traceback (most recent call last):
  File "/oasis/projects/nsf/azs119/edisj/Comet/benchmarks/vanilla_stripe/scripts/24/benchmark.py", line 204, in <module>
    times_array, rmsd_array = benchmark(topology, trajectory)
  File "/oasis/projects/nsf/azs119/edisj/Comet/benchmarks/vanilla_stripe/scripts/24/benchmark.py", line 58, in benchmark
    rmsd_array[i] = rmsd(CA.positions, x_ref, superposition=True)
IndexError: index 1877 is out of bounds for axis 0 with size 1877
Traceback (most recent call last):
  File "/oasis/projects/nsf/azs119/edisj/Comet/benchmarks/vanilla_stripe/scripts/24/benchmark.py", line 204, in <module>
    times_array, rmsd_array = benchmark(topology, trajectory)
  File "/oasis/projects/nsf/azs119/edisj/Comet/benchmarks/vanilla_stripe/scripts/24/benchmark.py", line 58, in benchmark
    rmsd_array[i] = rmsd(CA.positions, x_ref, superposition=True)
IndexError: index 1877 is out of bounds for axis 0 with size 1877
Traceback (most recent call last):
  File "/oasis/projects/nsf/azs119/edisj/Comet/benchmarks/vanilla_stripe/scripts/24/benchmark.py", line 204, in <module>
    times_array, rmsd_array = benchmark(topology, trajectory)
  File "/oasis/projects/nsf/azs119/edisj/Comet/benchmarks/vanilla_stripe/scripts/24/benchmark.py", line 58, in benchmark
    rmsd_array[i] = rmsd(CA.positions, x_ref, superposition=True)
IndexError: index 1877 is out of bounds for axis 0 with size 1877
Traceback (most recent call last):
  File "/oasis/projects/nsf/azs119/edisj/Comet/benchmarks/vanilla_stripe/scripts/24/benchmark.py", line 204, in <module>
    times_array, rmsd_array = benchmark(topology, trajectory)
  File "/oasis/projects/nsf/azs119/edisj/Comet/benchmarks/vanilla_stripe/scripts/24/benchmark.py", line 58, in benchmark
    rmsd_array[i] = rmsd(CA.positions, x_ref, superposition=True)
IndexError: index 1877 is out of bounds for axis 0 with size 1877
Traceback (most recent call last):
  File "/oasis/projects/nsf/azs119/edisj/Comet/benchmarks/vanilla_stripe/scripts/24/benchmark.py", line 204, in <module>
    times_array, rmsd_array = benchmark(topology, trajectory)
  File "/oasis/projects/nsf/azs119/edisj/Comet/benchmarks/vanilla_stripe/scripts/24/benchmark.py", line 58, in benchmark
    rmsd_array[i] = rmsd(CA.positions, x_ref, superposition=True)
IndexError: index 1877 is out of bounds for axis 0 with size 1877
Traceback (most recent call last):
  File "/oasis/projects/nsf/azs119/edisj/Comet/benchmarks/vanilla_stripe/scripts/24/benchmark.py", line 204, in <module>
    times_array, rmsd_array = benchmark(topology, trajectory)
  File "/oasis/projects/nsf/azs119/edisj/Comet/benchmarks/vanilla_stripe/scripts/24/benchmark.py", line 58, in benchmark
    rmsd_array[i] = rmsd(CA.positions, x_ref, superposition=True)
IndexError: index 1877 is out of bounds for axis 0 with size 1877
Traceback (most recent call last):
  File "/oasis/projects/nsf/azs119/edisj/Comet/benchmarks/vanilla_stripe/scripts/24/benchmark.py", line 204, in <module>
    times_array, rmsd_array = benchmark(topology, trajectory)
  File "/oasis/projects/nsf/azs119/edisj/Comet/benchmarks/vanilla_stripe/scripts/24/benchmark.py", line 58, in benchmark
    rmsd_array[i] = rmsd(CA.positions, x_ref, superposition=True)
IndexError: index 1877 is out of bounds for axis 0 with size 1877
Traceback (most recent call last):
  File "/oasis/projects/nsf/azs119/edisj/Comet/benchmarks/vanilla_stripe/scripts/24/benchmark.py", line 204, in <module>
    times_array, rmsd_array = benchmark(topology, trajectory)
  File "/oasis/projects/nsf/azs119/edisj/Comet/benchmarks/vanilla_stripe/scripts/24/benchmark.py", line 58, in benchmark
    rmsd_array[i] = rmsd(CA.positions, x_ref, superposition=True)
IndexError: index 1877 is out of bounds for axis 0 with size 1877
Traceback (most recent call last):
  File "/oasis/projects/nsf/azs119/edisj/Comet/benchmarks/vanilla_stripe/scripts/24/benchmark.py", line 204, in <module>
    times_array, rmsd_array = benchmark(topology, trajectory)
  File "/oasis/projects/nsf/azs119/edisj/Comet/benchmarks/vanilla_stripe/scripts/24/benchmark.py", line 58, in benchmark
    rmsd_array[i] = rmsd(CA.positions, x_ref, superposition=True)
IndexError: index 1877 is out of bounds for axis 0 with size 1877
Traceback (most recent call last):
  File "/oasis/projects/nsf/azs119/edisj/Comet/benchmarks/vanilla_stripe/scripts/24/benchmark.py", line 204, in <module>
    times_array, rmsd_array = benchmark(topology, trajectory)
  File "/oasis/projects/nsf/azs119/edisj/Comet/benchmarks/vanilla_stripe/scripts/24/benchmark.py", line 58, in benchmark
    rmsd_array[i] = rmsd(CA.positions, x_ref, superposition=True)
IndexError: index 1877 is out of bounds for axis 0 with size 1877
Traceback (most recent call last):
  File "/oasis/projects/nsf/azs119/edisj/Comet/benchmarks/vanilla_stripe/scripts/24/benchmark.py", line 204, in <module>
    times_array, rmsd_array = benchmark(topology, trajectory)
  File "/oasis/projects/nsf/azs119/edisj/Comet/benchmarks/vanilla_stripe/scripts/24/benchmark.py", line 58, in benchmark
    rmsd_array[i] = rmsd(CA.positions, x_ref, superposition=True)
IndexError: index 1878 is out of bounds for axis 0 with size 1878
Traceback (most recent call last):
  File "/oasis/projects/nsf/azs119/edisj/Comet/benchmarks/vanilla_stripe/scripts/24/benchmark.py", line 204, in <module>
    times_array, rmsd_array = benchmark(topology, trajectory)
  File "/oasis/projects/nsf/azs119/edisj/Comet/benchmarks/vanilla_stripe/scripts/24/benchmark.py", line 58, in benchmark
    rmsd_array[i] = rmsd(CA.positions, x_ref, superposition=True)
IndexError: index 1878 is out of bounds for axis 0 with size 1878
Traceback (most recent call last):
  File "/oasis/projects/nsf/azs119/edisj/Comet/benchmarks/vanilla_stripe/scripts/24/benchmark.py", line 204, in <module>
    times_array, rmsd_array = benchmark(topology, trajectory)
  File "/oasis/projects/nsf/azs119/edisj/Comet/benchmarks/vanilla_stripe/scripts/24/benchmark.py", line 58, in benchmark
    rmsd_array[i] = rmsd(CA.positions, x_ref, superposition=True)
IndexError: index 1878 is out of bounds for axis 0 with size 1878
Traceback (most recent call last):
  File "/oasis/projects/nsf/azs119/edisj/Comet/benchmarks/vanilla_stripe/scripts/24/benchmark.py", line 204, in <module>
    times_array, rmsd_array = benchmark(topology, trajectory)
  File "/oasis/projects/nsf/azs119/edisj/Comet/benchmarks/vanilla_stripe/scripts/24/benchmark.py", line 58, in benchmark
    rmsd_array[i] = rmsd(CA.positions, x_ref, superposition=True)
IndexError: index 1878 is out of bounds for axis 0 with size 1878
Exception ignored in: <object repr() failed>
Traceback (most recent call last):
  File "/home/edisj/mdanalysis/package/MDAnalysis/coordinates/base.py", line 2165, in __del__
  File "/home/edisj/mdanalysis/package/MDAnalysis/coordinates/H5MD.py", line 978, in close
  File "/home/edisj/anaconda3/envs/mda8/lib/python3.6/site-packages/h5py/_hl/files.py", line 445, in close
  File "h5py/_objects.pyx", line 54, in h5py._objects.with_phil.wrapper
  File "h5py/_objects.pyx", line 55, in h5py._objects.with_phil.wrapper
  File "h5py/h5f.pyx", line 275, in h5py.h5f.get_obj_ids
  File "h5py/h5i.pyx", line 46, in h5py.h5i.wrap_identifier
ImportError: sys.meta_path is None, Python is likely shutting down
Traceback (most recent call last):
  File "h5py/_objects.pyx", line 199, in h5py._objects.ObjectID.__dealloc__
RuntimeError: Can't decrement id ref count (can't close file, there are objects still open)
Exception ignored in: 'h5py._objects.ObjectID.__dealloc__'
Traceback (most recent call last):
  File "h5py/_objects.pyx", line 199, in h5py._objects.ObjectID.__dealloc__
RuntimeError: Can't decrement id ref count (can't close file, there are objects still open)
Exception ignored in: <object repr() failed>
Traceback (most recent call last):
  File "/home/edisj/mdanalysis/package/MDAnalysis/coordinates/base.py", line 2165, in __del__
  File "/home/edisj/mdanalysis/package/MDAnalysis/coordinates/H5MD.py", line 978, in close
  File "/home/edisj/anaconda3/envs/mda8/lib/python3.6/site-packages/h5py/_hl/files.py", line 445, in close
  File "h5py/_objects.pyx", line 54, in h5py._objects.with_phil.wrapper
  File "h5py/_objects.pyx", line 55, in h5py._objects.with_phil.wrapper
  File "h5py/h5f.pyx", line 275, in h5py.h5f.get_obj_ids
  File "h5py/h5i.pyx", line 46, in h5py.h5i.wrap_identifier
ImportError: sys.meta_path is None, Python is likely shutting down
Traceback (most recent call last):
  File "h5py/_objects.pyx", line 199, in h5py._objects.ObjectID.__dealloc__
RuntimeError: Can't decrement id ref count (can't close file, there are objects still open)
Exception ignored in: 'h5py._objects.ObjectID.__dealloc__'
Traceback (most recent call last):
  File "h5py/_objects.pyx", line 199, in h5py._objects.ObjectID.__dealloc__
RuntimeError: Can't decrement id ref count (can't close file, there are objects still open)
Exception ignored in: <object repr() failed>
Traceback (most recent call last):
  File "/home/edisj/mdanalysis/package/MDAnalysis/coordinates/base.py", line 2165, in __del__
  File "/home/edisj/mdanalysis/package/MDAnalysis/coordinates/H5MD.py", line 978, in close
  File "/home/edisj/anaconda3/envs/mda8/lib/python3.6/site-packages/h5py/_hl/files.py", line 445, in close
  File "h5py/_objects.pyx", line 54, in h5py._objects.with_phil.wrapper
  File "h5py/_objects.pyx", line 55, in h5py._objects.with_phil.wrapper
  File "h5py/h5f.pyx", line 275, in h5py.h5f.get_obj_ids
  File "h5py/h5i.pyx", line 46, in h5py.h5i.wrap_identifier
ImportError: sys.meta_path is None, Python is likely shutting down
Traceback (most recent call last):
  File "h5py/_objects.pyx", line 199, in h5py._objects.ObjectID.__dealloc__
RuntimeError: Can't decrement id ref count (can't close file, there are objects still open)
Exception ignored in: 'h5py._objects.ObjectID.__dealloc__'
Traceback (most recent call last):
  File "h5py/_objects.pyx", line 199, in h5py._objects.ObjectID.__dealloc__
RuntimeError: Can't decrement id ref count (can't close file, there are objects still open)
Exception ignored in: <object repr() failed>
Traceback (most recent call last):
  File "/home/edisj/mdanalysis/package/MDAnalysis/coordinates/base.py", line 2165, in __del__
  File "/home/edisj/mdanalysis/package/MDAnalysis/coordinates/H5MD.py", line 978, in close
  File "/home/edisj/anaconda3/envs/mda8/lib/python3.6/site-packages/h5py/_hl/files.py", line 445, in close
  File "h5py/_objects.pyx", line 54, in h5py._objects.with_phil.wrapper
  File "h5py/_objects.pyx", line 55, in h5py._objects.with_phil.wrapper
  File "h5py/h5f.pyx", line 275, in h5py.h5f.get_obj_ids
  File "h5py/h5i.pyx", line 46, in h5py.h5i.wrap_identifier
ImportError: sys.meta_path is None, Python is likely shutting down
Traceback (most recent call last):
  File "h5py/_objects.pyx", line 199, in h5py._objects.ObjectID.__dealloc__
RuntimeError: Can't decrement id ref count (can't close file, there are objects still open)
Exception ignored in: 'h5py._objects.ObjectID.__dealloc__'
Traceback (most recent call last):
  File "h5py/_objects.pyx", line 199, in h5py._objects.ObjectID.__dealloc__
RuntimeError: Can't decrement id ref count (can't close file, there are objects still open)
Exception ignored in: <object repr() failed>
Traceback (most recent call last):
  File "/home/edisj/mdanalysis/package/MDAnalysis/coordinates/base.py", line 2165, in __del__
  File "/home/edisj/mdanalysis/package/MDAnalysis/coordinates/H5MD.py", line 978, in close
  File "/home/edisj/anaconda3/envs/mda8/lib/python3.6/site-packages/h5py/_hl/files.py", line 445, in close
  File "h5py/_objects.pyx", line 54, in h5py._objects.with_phil.wrapper
  File "h5py/_objects.pyx", line 55, in h5py._objects.with_phil.wrapper
  File "h5py/h5f.pyx", line 275, in h5py.h5f.get_obj_ids
  File "h5py/h5i.pyx", line 46, in h5py.h5i.wrap_identifier
ImportError: sys.meta_path is None, Python is likely shutting down
Traceback (most recent call last):
  File "h5py/_objects.pyx", line 199, in h5py._objects.ObjectID.__dealloc__
RuntimeError: Can't decrement id ref count (can't close file, there are objects still open)
Exception ignored in: 'h5py._objects.ObjectID.__dealloc__'
Traceback (most recent call last):
  File "h5py/_objects.pyx", line 199, in h5py._objects.ObjectID.__dealloc__
RuntimeError: Can't decrement id ref count (can't close file, there are objects still open)
Exception ignored in: <object repr() failed>
Traceback (most recent call last):
  File "/home/edisj/mdanalysis/package/MDAnalysis/coordinates/base.py", line 2165, in __del__
  File "/home/edisj/mdanalysis/package/MDAnalysis/coordinates/H5MD.py", line 978, in close
  File "/home/edisj/anaconda3/envs/mda8/lib/python3.6/site-packages/h5py/_hl/files.py", line 445, in close
  File "h5py/_objects.pyx", line 54, in h5py._objects.with_phil.wrapper
  File "h5py/_objects.pyx", line 55, in h5py._objects.with_phil.wrapper
  File "h5py/h5f.pyx", line 275, in h5py.h5f.get_obj_ids
  File "h5py/h5i.pyx", line 46, in h5py.h5i.wrap_identifier
ImportError: sys.meta_path is None, Python is likely shutting down
Traceback (most recent call last):
  File "h5py/_objects.pyx", line 199, in h5py._objects.ObjectID.__dealloc__
RuntimeError: Can't decrement id ref count (can't close file, there are objects still open)
Exception ignored in: 'h5py._objects.ObjectID.__dealloc__'
Traceback (most recent call last):
  File "h5py/_objects.pyx", line 199, in h5py._objects.ObjectID.__dealloc__
RuntimeError: Can't decrement id ref count (can't close file, there are objects still open)
Exception ignored in: <object repr() failed>
Traceback (most recent call last):
  File "/home/edisj/mdanalysis/package/MDAnalysis/coordinates/base.py", line 2165, in __del__
  File "/home/edisj/mdanalysis/package/MDAnalysis/coordinates/H5MD.py", line 978, in close
  File "/home/edisj/anaconda3/envs/mda8/lib/python3.6/site-packages/h5py/_hl/files.py", line 445, in close
  File "h5py/_objects.pyx", line 54, in h5py._objects.with_phil.wrapper
  File "h5py/_objects.pyx", line 55, in h5py._objects.with_phil.wrapper
  File "h5py/h5f.pyx", line 275, in h5py.h5f.get_obj_ids
  File "h5py/h5i.pyx", line 46, in h5py.h5i.wrap_identifier
ImportError: sys.meta_path is None, Python is likely shutting down
Traceback (most recent call last):
  File "h5py/_objects.pyx", line 199, in h5py._objects.ObjectID.__dealloc__
RuntimeError: Can't decrement id ref count (can't close file, there are objects still open)
Exception ignored in: 'h5py._objects.ObjectID.__dealloc__'
Traceback (most recent call last):
  File "h5py/_objects.pyx", line 199, in h5py._objects.ObjectID.__dealloc__
RuntimeError: Can't decrement id ref count (can't close file, there are objects still open)
Exception ignored in: <object repr() failed>
Traceback (most recent call last):
  File "/home/edisj/mdanalysis/package/MDAnalysis/coordinates/base.py", line 2165, in __del__
  File "/home/edisj/mdanalysis/package/MDAnalysis/coordinates/H5MD.py", line 978, in close
  File "/home/edisj/anaconda3/envs/mda8/lib/python3.6/site-packages/h5py/_hl/files.py", line 445, in close
  File "h5py/_objects.pyx", line 54, in h5py._objects.with_phil.wrapper
  File "h5py/_objects.pyx", line 55, in h5py._objects.with_phil.wrapper
  File "h5py/h5f.pyx", line 275, in h5py.h5f.get_obj_ids
  File "h5py/h5i.pyx", line 46, in h5py.h5i.wrap_identifier
ImportError: sys.meta_path is None, Python is likely shutting down
Traceback (most recent call last):
  File "h5py/_objects.pyx", line 199, in h5py._objects.ObjectID.__dealloc__
RuntimeError: Can't decrement id ref count (can't close file, there are objects still open)
Exception ignored in: 'h5py._objects.ObjectID.__dealloc__'
Traceback (most recent call last):
  File "h5py/_objects.pyx", line 199, in h5py._objects.ObjectID.__dealloc__
RuntimeError: Can't decrement id ref count (can't close file, there are objects still open)
Exception ignored in: <object repr() failed>
Traceback (most recent call last):
  File "/home/edisj/mdanalysis/package/MDAnalysis/coordinates/base.py", line 2165, in __del__
  File "/home/edisj/mdanalysis/package/MDAnalysis/coordinates/H5MD.py", line 978, in close
  File "/home/edisj/anaconda3/envs/mda8/lib/python3.6/site-packages/h5py/_hl/files.py", line 445, in close
  File "h5py/_objects.pyx", line 54, in h5py._objects.with_phil.wrapper
  File "h5py/_objects.pyx", line 55, in h5py._objects.with_phil.wrapper
  File "h5py/h5f.pyx", line 275, in h5py.h5f.get_obj_ids
  File "h5py/h5i.pyx", line 46, in h5py.h5i.wrap_identifier
ImportError: sys.meta_path is None, Python is likely shutting down
Traceback (most recent call last):
  File "h5py/_objects.pyx", line 199, in h5py._objects.ObjectID.__dealloc__
RuntimeError: Can't decrement id ref count (can't close file, there are objects still open)
Exception ignored in: 'h5py._objects.ObjectID.__dealloc__'
Traceback (most recent call last):
  File "h5py/_objects.pyx", line 199, in h5py._objects.ObjectID.__dealloc__
RuntimeError: Can't decrement id ref count (can't close file, there are objects still open)
Exception ignored in: <object repr() failed>
Traceback (most recent call last):
  File "/home/edisj/mdanalysis/package/MDAnalysis/coordinates/base.py", line 2165, in __del__
  File "/home/edisj/mdanalysis/package/MDAnalysis/coordinates/H5MD.py", line 978, in close
  File "/home/edisj/anaconda3/envs/mda8/lib/python3.6/site-packages/h5py/_hl/files.py", line 445, in close
  File "h5py/_objects.pyx", line 54, in h5py._objects.with_phil.wrapper
  File "h5py/_objects.pyx", line 55, in h5py._objects.with_phil.wrapper
  File "h5py/h5f.pyx", line 275, in h5py.h5f.get_obj_ids
  File "h5py/h5i.pyx", line 46, in h5py.h5i.wrap_identifier
ImportError: sys.meta_path is None, Python is likely shutting down
Traceback (most recent call last):
  File "h5py/_objects.pyx", line 199, in h5py._objects.ObjectID.__dealloc__
RuntimeError: Can't decrement id ref count (can't close file, there are objects still open)
Exception ignored in: 'h5py._objects.ObjectID.__dealloc__'
Traceback (most recent call last):
  File "h5py/_objects.pyx", line 199, in h5py._objects.ObjectID.__dealloc__
RuntimeError: Can't decrement id ref count (can't close file, there are objects still open)
Exception ignored in: <object repr() failed>
Traceback (most recent call last):
  File "/home/edisj/mdanalysis/package/MDAnalysis/coordinates/base.py", line 2165, in __del__
  File "/home/edisj/mdanalysis/package/MDAnalysis/coordinates/H5MD.py", line 978, in close
  File "/home/edisj/anaconda3/envs/mda8/lib/python3.6/site-packages/h5py/_hl/files.py", line 445, in close
  File "h5py/_objects.pyx", line 54, in h5py._objects.with_phil.wrapper
  File "h5py/_objects.pyx", line 55, in h5py._objects.with_phil.wrapper
  File "h5py/h5f.pyx", line 275, in h5py.h5f.get_obj_ids
  File "h5py/h5i.pyx", line 46, in h5py.h5i.wrap_identifier
ImportError: sys.meta_path is None, Python is likely shutting down
Traceback (most recent call last):
  File "h5py/_objects.pyx", line 199, in h5py._objects.ObjectID.__dealloc__
RuntimeError: Can't decrement id ref count (can't close file, there are objects still open)
Exception ignored in: 'h5py._objects.ObjectID.__dealloc__'
Traceback (most recent call last):
  File "h5py/_objects.pyx", line 199, in h5py._objects.ObjectID.__dealloc__
RuntimeError: Can't decrement id ref count (can't close file, there are objects still open)
Exception ignored in: <object repr() failed>
Traceback (most recent call last):
  File "/home/edisj/mdanalysis/package/MDAnalysis/coordinates/base.py", line 2165, in __del__
  File "/home/edisj/mdanalysis/package/MDAnalysis/coordinates/H5MD.py", line 978, in close
  File "/home/edisj/anaconda3/envs/mda8/lib/python3.6/site-packages/h5py/_hl/files.py", line 445, in close
  File "h5py/_objects.pyx", line 54, in h5py._objects.with_phil.wrapper
  File "h5py/_objects.pyx", line 55, in h5py._objects.with_phil.wrapper
  File "h5py/h5f.pyx", line 275, in h5py.h5f.get_obj_ids
  File "h5py/h5i.pyx", line 46, in h5py.h5i.wrap_identifier
ImportError: sys.meta_path is None, Python is likely shutting down
Traceback (most recent call last):
  File "h5py/_objects.pyx", line 199, in h5py._objects.ObjectID.__dealloc__
RuntimeError: Can't decrement id ref count (can't close file, there are objects still open)
Exception ignored in: 'h5py._objects.ObjectID.__dealloc__'
Traceback (most recent call last):
  File "h5py/_objects.pyx", line 199, in h5py._objects.ObjectID.__dealloc__
RuntimeError: Can't decrement id ref count (can't close file, there are objects still open)
Exception ignored in: <object repr() failed>
Traceback (most recent call last):
  File "/home/edisj/mdanalysis/package/MDAnalysis/coordinates/base.py", line 2165, in __del__
  File "/home/edisj/mdanalysis/package/MDAnalysis/coordinates/H5MD.py", line 978, in close
  File "/home/edisj/anaconda3/envs/mda8/lib/python3.6/site-packages/h5py/_hl/files.py", line 445, in close
  File "h5py/_objects.pyx", line 54, in h5py._objects.with_phil.wrapper
  File "h5py/_objects.pyx", line 55, in h5py._objects.with_phil.wrapper
  File "h5py/h5f.pyx", line 275, in h5py.h5f.get_obj_ids
  File "h5py/h5i.pyx", line 46, in h5py.h5i.wrap_identifier
ImportError: sys.meta_path is None, Python is likely shutting down
Traceback (most recent call last):
  File "h5py/_objects.pyx", line 199, in h5py._objects.ObjectID.__dealloc__
RuntimeError: Can't decrement id ref count (can't close file, there are objects still open)
Exception ignored in: 'h5py._objects.ObjectID.__dealloc__'
Traceback (most recent call last):
  File "h5py/_objects.pyx", line 199, in h5py._objects.ObjectID.__dealloc__
RuntimeError: Can't decrement id ref count (can't close file, there are objects still open)
Exception ignored in: <object repr() failed>
Traceback (most recent call last):
  File "/home/edisj/mdanalysis/package/MDAnalysis/coordinates/base.py", line 2165, in __del__
  File "/home/edisj/mdanalysis/package/MDAnalysis/coordinates/H5MD.py", line 978, in close
  File "/home/edisj/anaconda3/envs/mda8/lib/python3.6/site-packages/h5py/_hl/files.py", line 445, in close
  File "h5py/_objects.pyx", line 54, in h5py._objects.with_phil.wrapper
  File "h5py/_objects.pyx", line 55, in h5py._objects.with_phil.wrapper
  File "h5py/h5f.pyx", line 275, in h5py.h5f.get_obj_ids
  File "h5py/h5i.pyx", line 46, in h5py.h5i.wrap_identifier
ImportError: sys.meta_path is None, Python is likely shutting down
Traceback (most recent call last):
  File "h5py/_objects.pyx", line 199, in h5py._objects.ObjectID.__dealloc__
RuntimeError: Can't decrement id ref count (can't close file, there are objects still open)
Exception ignored in: 'h5py._objects.ObjectID.__dealloc__'
Traceback (most recent call last):
  File "h5py/_objects.pyx", line 199, in h5py._objects.ObjectID.__dealloc__
RuntimeError: Can't decrement id ref count (can't close file, there are objects still open)
Exception ignored in: <object repr() failed>
Traceback (most recent call last):
  File "/home/edisj/mdanalysis/package/MDAnalysis/coordinates/base.py", line 2165, in __del__
  File "/home/edisj/mdanalysis/package/MDAnalysis/coordinates/H5MD.py", line 978, in close
  File "/home/edisj/anaconda3/envs/mda8/lib/python3.6/site-packages/h5py/_hl/files.py", line 445, in close
  File "h5py/_objects.pyx", line 54, in h5py._objects.with_phil.wrapper
  File "h5py/_objects.pyx", line 55, in h5py._objects.with_phil.wrapper
  File "h5py/h5f.pyx", line 275, in h5py.h5f.get_obj_ids
  File "h5py/h5i.pyx", line 46, in h5py.h5i.wrap_identifier
ImportError: sys.meta_path is None, Python is likely shutting down
Traceback (most recent call last):
  File "h5py/_objects.pyx", line 199, in h5py._objects.ObjectID.__dealloc__
RuntimeError: Can't decrement id ref count (can't close file, there are objects still open)
Exception ignored in: 'h5py._objects.ObjectID.__dealloc__'
Traceback (most recent call last):
  File "h5py/_objects.pyx", line 199, in h5py._objects.ObjectID.__dealloc__
RuntimeError: Can't decrement id ref count (can't close file, there are objects still open)
Exception ignored in: <object repr() failed>
Traceback (most recent call last):
  File "/home/edisj/mdanalysis/package/MDAnalysis/coordinates/base.py", line 2165, in __del__
  File "/home/edisj/mdanalysis/package/MDAnalysis/coordinates/H5MD.py", line 978, in close
  File "/home/edisj/anaconda3/envs/mda8/lib/python3.6/site-packages/h5py/_hl/files.py", line 445, in close
  File "h5py/_objects.pyx", line 54, in h5py._objects.with_phil.wrapper
  File "h5py/_objects.pyx", line 55, in h5py._objects.with_phil.wrapper
  File "h5py/h5f.pyx", line 275, in h5py.h5f.get_obj_ids
  File "h5py/h5i.pyx", line 46, in h5py.h5i.wrap_identifier
ImportError: sys.meta_path is None, Python is likely shutting down
Traceback (most recent call last):
  File "h5py/_objects.pyx", line 199, in h5py._objects.ObjectID.__dealloc__
RuntimeError: Can't decrement id ref count (can't close file, there are objects still open)
Exception ignored in: 'h5py._objects.ObjectID.__dealloc__'
Traceback (most recent call last):
  File "h5py/_objects.pyx", line 199, in h5py._objects.ObjectID.__dealloc__
RuntimeError: Can't decrement id ref count (can't close file, there are objects still open)
Exception ignored in: <object repr() failed>
Traceback (most recent call last):
  File "/home/edisj/mdanalysis/package/MDAnalysis/coordinates/base.py", line 2165, in __del__
  File "/home/edisj/mdanalysis/package/MDAnalysis/coordinates/H5MD.py", line 978, in close
  File "/home/edisj/anaconda3/envs/mda8/lib/python3.6/site-packages/h5py/_hl/files.py", line 445, in close
  File "h5py/_objects.pyx", line 54, in h5py._objects.with_phil.wrapper
  File "h5py/_objects.pyx", line 55, in h5py._objects.with_phil.wrapper
  File "h5py/h5f.pyx", line 275, in h5py.h5f.get_obj_ids
  File "h5py/h5i.pyx", line 46, in h5py.h5i.wrap_identifier
ImportError: sys.meta_path is None, Python is likely shutting down
Traceback (most recent call last):
  File "h5py/_objects.pyx", line 199, in h5py._objects.ObjectID.__dealloc__
RuntimeError: Can't decrement id ref count (can't close file, there are objects still open)
Exception ignored in: 'h5py._objects.ObjectID.__dealloc__'
Traceback (most recent call last):
  File "h5py/_objects.pyx", line 199, in h5py._objects.ObjectID.__dealloc__
RuntimeError: Can't decrement id ref count (can't close file, there are objects still open)
Exception ignored in: <object repr() failed>
Traceback (most recent call last):
  File "/home/edisj/mdanalysis/package/MDAnalysis/coordinates/base.py", line 2165, in __del__
  File "/home/edisj/mdanalysis/package/MDAnalysis/coordinates/H5MD.py", line 978, in close
  File "/home/edisj/anaconda3/envs/mda8/lib/python3.6/site-packages/h5py/_hl/files.py", line 445, in close
  File "h5py/_objects.pyx", line 54, in h5py._objects.with_phil.wrapper
  File "h5py/_objects.pyx", line 55, in h5py._objects.with_phil.wrapper
  File "h5py/h5f.pyx", line 275, in h5py.h5f.get_obj_ids
  File "h5py/h5i.pyx", line 46, in h5py.h5i.wrap_identifier
ImportError: sys.meta_path is None, Python is likely shutting down
Traceback (most recent call last):
  File "h5py/_objects.pyx", line 199, in h5py._objects.ObjectID.__dealloc__
RuntimeError: Can't decrement id ref count (can't close file, there are objects still open)
Exception ignored in: 'h5py._objects.ObjectID.__dealloc__'
Traceback (most recent call last):
  File "h5py/_objects.pyx", line 199, in h5py._objects.ObjectID.__dealloc__
RuntimeError: Can't decrement id ref count (can't close file, there are objects still open)
Exception ignored in: <object repr() failed>
Traceback (most recent call last):
  File "/home/edisj/mdanalysis/package/MDAnalysis/coordinates/base.py", line 2165, in __del__
  File "/home/edisj/mdanalysis/package/MDAnalysis/coordinates/H5MD.py", line 978, in close
  File "/home/edisj/anaconda3/envs/mda8/lib/python3.6/site-packages/h5py/_hl/files.py", line 445, in close
  File "h5py/_objects.pyx", line 54, in h5py._objects.with_phil.wrapper
  File "h5py/_objects.pyx", line 55, in h5py._objects.with_phil.wrapper
  File "h5py/h5f.pyx", line 275, in h5py.h5f.get_obj_ids
  File "h5py/h5i.pyx", line 46, in h5py.h5i.wrap_identifier
ImportError: sys.meta_path is None, Python is likely shutting down
Traceback (most recent call last):
  File "h5py/_objects.pyx", line 199, in h5py._objects.ObjectID.__dealloc__
RuntimeError: Can't decrement id ref count (can't close file, there are objects still open)
Exception ignored in: 'h5py._objects.ObjectID.__dealloc__'
Traceback (most recent call last):
  File "h5py/_objects.pyx", line 199, in h5py._objects.ObjectID.__dealloc__
RuntimeError: Can't decrement id ref count (can't close file, there are objects still open)
Exception ignored in: <object repr() failed>
Traceback (most recent call last):
  File "/home/edisj/mdanalysis/package/MDAnalysis/coordinates/base.py", line 2165, in __del__
  File "/home/edisj/mdanalysis/package/MDAnalysis/coordinates/H5MD.py", line 978, in close
  File "/home/edisj/anaconda3/envs/mda8/lib/python3.6/site-packages/h5py/_hl/files.py", line 445, in close
  File "h5py/_objects.pyx", line 54, in h5py._objects.with_phil.wrapper
  File "h5py/_objects.pyx", line 55, in h5py._objects.with_phil.wrapper
  File "h5py/h5f.pyx", line 275, in h5py.h5f.get_obj_ids
  File "h5py/h5i.pyx", line 46, in h5py.h5i.wrap_identifier
ImportError: sys.meta_path is None, Python is likely shutting down
Traceback (most recent call last):
  File "h5py/_objects.pyx", line 199, in h5py._objects.ObjectID.__dealloc__
RuntimeError: Can't decrement id ref count (can't close file, there are objects still open)
Exception ignored in: 'h5py._objects.ObjectID.__dealloc__'
Traceback (most recent call last):
  File "h5py/_objects.pyx", line 199, in h5py._objects.ObjectID.__dealloc__
RuntimeError: Can't decrement id ref count (can't close file, there are objects still open)
Exception ignored in: <object repr() failed>
Traceback (most recent call last):
  File "/home/edisj/mdanalysis/package/MDAnalysis/coordinates/base.py", line 2165, in __del__
  File "/home/edisj/mdanalysis/package/MDAnalysis/coordinates/H5MD.py", line 978, in close
  File "/home/edisj/anaconda3/envs/mda8/lib/python3.6/site-packages/h5py/_hl/files.py", line 445, in close
  File "h5py/_objects.pyx", line 54, in h5py._objects.with_phil.wrapper
  File "h5py/_objects.pyx", line 55, in h5py._objects.with_phil.wrapper
  File "h5py/h5f.pyx", line 275, in h5py.h5f.get_obj_ids
  File "h5py/h5i.pyx", line 46, in h5py.h5i.wrap_identifier
ImportError: sys.meta_path is None, Python is likely shutting down
Traceback (most recent call last):
  File "h5py/_objects.pyx", line 199, in h5py._objects.ObjectID.__dealloc__
RuntimeError: Can't decrement id ref count (can't close file, there are objects still open)
Exception ignored in: 'h5py._objects.ObjectID.__dealloc__'
Traceback (most recent call last):
  File "h5py/_objects.pyx", line 199, in h5py._objects.ObjectID.__dealloc__
RuntimeError: Can't decrement id ref count (can't close file, there are objects still open)
Exception ignored in: <object repr() failed>
Traceback (most recent call last):
  File "/home/edisj/mdanalysis/package/MDAnalysis/coordinates/base.py", line 2165, in __del__
  File "/home/edisj/mdanalysis/package/MDAnalysis/coordinates/H5MD.py", line 978, in close
  File "/home/edisj/anaconda3/envs/mda8/lib/python3.6/site-packages/h5py/_hl/files.py", line 445, in close
  File "h5py/_objects.pyx", line 54, in h5py._objects.with_phil.wrapper
  File "h5py/_objects.pyx", line 55, in h5py._objects.with_phil.wrapper
  File "h5py/h5f.pyx", line 275, in h5py.h5f.get_obj_ids
  File "h5py/h5i.pyx", line 46, in h5py.h5i.wrap_identifier
ImportError: sys.meta_path is None, Python is likely shutting down
Traceback (most recent call last):
  File "h5py/_objects.pyx", line 199, in h5py._objects.ObjectID.__dealloc__
RuntimeError: Can't decrement id ref count (can't close file, there are objects still open)
Exception ignored in: 'h5py._objects.ObjectID.__dealloc__'
Traceback (most recent call last):
  File "h5py/_objects.pyx", line 199, in h5py._objects.ObjectID.__dealloc__
RuntimeError: Can't decrement id ref count (can't close file, there are objects still open)
Exception ignored in: <object repr() failed>
Traceback (most recent call last):
  File "/home/edisj/mdanalysis/package/MDAnalysis/coordinates/base.py", line 2165, in __del__
  File "/home/edisj/mdanalysis/package/MDAnalysis/coordinates/H5MD.py", line 978, in close
  File "/home/edisj/anaconda3/envs/mda8/lib/python3.6/site-packages/h5py/_hl/files.py", line 445, in close
  File "h5py/_objects.pyx", line 54, in h5py._objects.with_phil.wrapper
  File "h5py/_objects.pyx", line 55, in h5py._objects.with_phil.wrapper
  File "h5py/h5f.pyx", line 275, in h5py.h5f.get_obj_ids
  File "h5py/h5i.pyx", line 46, in h5py.h5i.wrap_identifier
ImportError: sys.meta_path is None, Python is likely shutting down
Traceback (most recent call last):
  File "h5py/_objects.pyx", line 199, in h5py._objects.ObjectID.__dealloc__
RuntimeError: Can't decrement id ref count (can't close file, there are objects still open)
Exception ignored in: 'h5py._objects.ObjectID.__dealloc__'
Traceback (most recent call last):
  File "h5py/_objects.pyx", line 199, in h5py._objects.ObjectID.__dealloc__
RuntimeError: Can't decrement id ref count (can't close file, there are objects still open)
Exception ignored in: <object repr() failed>
Traceback (most recent call last):
  File "/home/edisj/mdanalysis/package/MDAnalysis/coordinates/base.py", line 2165, in __del__
  File "/home/edisj/mdanalysis/package/MDAnalysis/coordinates/H5MD.py", line 978, in close
  File "/home/edisj/anaconda3/envs/mda8/lib/python3.6/site-packages/h5py/_hl/files.py", line 445, in close
  File "h5py/_objects.pyx", line 54, in h5py._objects.with_phil.wrapper
  File "h5py/_objects.pyx", line 55, in h5py._objects.with_phil.wrapper
  File "h5py/h5f.pyx", line 275, in h5py.h5f.get_obj_ids
  File "h5py/h5i.pyx", line 46, in h5py.h5i.wrap_identifier
ImportError: sys.meta_path is None, Python is likely shutting down
Traceback (most recent call last):
  File "h5py/_objects.pyx", line 199, in h5py._objects.ObjectID.__dealloc__
RuntimeError: Can't decrement id ref count (can't close file, there are objects still open)
Exception ignored in: 'h5py._objects.ObjectID.__dealloc__'
Traceback (most recent call last):
  File "h5py/_objects.pyx", line 199, in h5py._objects.ObjectID.__dealloc__
RuntimeError: Can't decrement id ref count (can't close file, there are objects still open)
*** The MPI_File_close() function was called after MPI_FINALIZE was invoked.
*** This is disallowed by the MPI standard.
*** Your MPI job will now abort.
[comet-20-55.sdsc.edu:30734] Local abort after MPI_FINALIZE started completed successfully, but am not able to aggregate error messages, and not able to guarantee that all other processes were killed!
*** The MPI_File_close() function was called after MPI_FINALIZE was invoked.
*** This is disallowed by the MPI standard.
*** Your MPI job will now abort.
[comet-20-56.sdsc.edu:30749] Local abort after MPI_FINALIZE started completed successfully, but am not able to aggregate error messages, and not able to guarantee that all other processes were killed!
*** The MPI_File_close() function was called after MPI_FINALIZE was invoked.
*** This is disallowed by the MPI standard.
*** Your MPI job will now abort.
[comet-20-56.sdsc.edu:30729] Local abort after MPI_FINALIZE started completed successfully, but am not able to aggregate error messages, and not able to guarantee that all other processes were killed!
*** The MPI_File_close() function was called after MPI_FINALIZE was invoked.
*** This is disallowed by the MPI standard.
*** Your MPI job will now abort.
[comet-20-55.sdsc.edu:30751] Local abort after MPI_FINALIZE started completed successfully, but am not able to aggregate error messages, and not able to guarantee that all other processes were killed!
*** The MPI_File_close() function was called after MPI_FINALIZE was invoked.
*** This is disallowed by the MPI standard.
*** Your MPI job will now abort.
[comet-20-56.sdsc.edu:30728] Local abort after MPI_FINALIZE started completed successfully, but am not able to aggregate error messages, and not able to guarantee that all other processes were killed!
*** The MPI_File_close() function was called after MPI_FINALIZE was invoked.
*** This is disallowed by the MPI standard.
*** Your MPI job will now abort.
[comet-20-56.sdsc.edu:30752] Local abort after MPI_FINALIZE started completed successfully, but am not able to aggregate error messages, and not able to guarantee that all other processes were killed!
*** The MPI_File_close() function was called after MPI_FINALIZE was invoked.
*** This is disallowed by the MPI standard.
*** Your MPI job will now abort.
[comet-20-56.sdsc.edu:30735] Local abort after MPI_FINALIZE started completed successfully, but am not able to aggregate error messages, and not able to guarantee that all other processes were killed!
*** The MPI_File_close() function was called after MPI_FINALIZE was invoked.
*** This is disallowed by the MPI standard.
*** Your MPI job will now abort.
[comet-20-56.sdsc.edu:30750] Local abort after MPI_FINALIZE started completed successfully, but am not able to aggregate error messages, and not able to guarantee that all other processes were killed!
*** The MPI_File_close() function was called after MPI_FINALIZE was invoked.
*** This is disallowed by the MPI standard.
*** Your MPI job will now abort.
[comet-20-56.sdsc.edu:30733] Local abort after MPI_FINALIZE started completed successfully, but am not able to aggregate error messages, and not able to guarantee that all other processes were killed!
*** The MPI_File_close() function was called after MPI_FINALIZE was invoked.
*** This is disallowed by the MPI standard.
*** Your MPI job will now abort.
[comet-20-55.sdsc.edu:30738] Local abort after MPI_FINALIZE started completed successfully, but am not able to aggregate error messages, and not able to guarantee that all other processes were killed!
*** The MPI_File_close() function was called after MPI_FINALIZE was invoked.
*** This is disallowed by the MPI standard.
*** Your MPI job will now abort.
[comet-20-55.sdsc.edu:30737] Local abort after MPI_FINALIZE started completed successfully, but am not able to aggregate error messages, and not able to guarantee that all other processes were killed!
*** The MPI_File_close() function was called after MPI_FINALIZE was invoked.
*** This is disallowed by the MPI standard.
*** Your MPI job will now abort.
[comet-20-55.sdsc.edu:30753] Local abort after MPI_FINALIZE started completed successfully, but am not able to aggregate error messages, and not able to guarantee that all other processes were killed!
*** The MPI_File_close() function was called after MPI_FINALIZE was invoked.
*** This is disallowed by the MPI standard.
*** Your MPI job will now abort.
[comet-20-55.sdsc.edu:30749] Local abort after MPI_FINALIZE started completed successfully, but am not able to aggregate error messages, and not able to guarantee that all other processes were killed!
*** The MPI_File_close() function was called after MPI_FINALIZE was invoked.
*** This is disallowed by the MPI standard.
*** Your MPI job will now abort.
[comet-20-55.sdsc.edu:30736] Local abort after MPI_FINALIZE started completed successfully, but am not able to aggregate error messages, and not able to guarantee that all other processes were killed!
--------------------------------------------------------------------------
Primary job  terminated normally, but 1 process returned
a non-zero exit code. Per user-direction, the job has been aborted.
--------------------------------------------------------------------------
*** The MPI_File_close() function was called after MPI_FINALIZE was invoked.
*** This is disallowed by the MPI standard.
*** Your MPI job will now abort.
[comet-20-56.sdsc.edu:30751] Local abort after MPI_FINALIZE started completed successfully, but am not able to aggregate error messages, and not able to guarantee that all other processes were killed!
*** The MPI_File_close() function was called after MPI_FINALIZE was invoked.
*** This is disallowed by the MPI standard.
*** Your MPI job will now abort.
[comet-20-56.sdsc.edu:30745] Local abort after MPI_FINALIZE started completed successfully, but am not able to aggregate error messages, and not able to guarantee that all other processes were killed!
*** The MPI_File_close() function was called after MPI_FINALIZE was invoked.
*** This is disallowed by the MPI standard.
*** Your MPI job will now abort.
[comet-20-56.sdsc.edu:30737] Local abort after MPI_FINALIZE started completed successfully, but am not able to aggregate error messages, and not able to guarantee that all other processes were killed!
*** The MPI_File_close() function was called after MPI_FINALIZE was invoked.
*** This is disallowed by the MPI standard.
*** Your MPI job will now abort.
[comet-20-56.sdsc.edu:30736] Local abort after MPI_FINALIZE started completed successfully, but am not able to aggregate error messages, and not able to guarantee that all other processes were killed!
*** The MPI_File_close() function was called after MPI_FINALIZE was invoked.
*** This is disallowed by the MPI standard.
*** Your MPI job will now abort.
[comet-20-55.sdsc.edu:30743] Local abort after MPI_FINALIZE started completed successfully, but am not able to aggregate error messages, and not able to guarantee that all other processes were killed!
*** The MPI_File_close() function was called after MPI_FINALIZE was invoked.
*** This is disallowed by the MPI standard.
*** Your MPI job will now abort.
[comet-20-55.sdsc.edu:30730] Local abort after MPI_FINALIZE started completed successfully, but am not able to aggregate error messages, and not able to guarantee that all other processes were killed!
*** The MPI_File_close() function was called after MPI_FINALIZE was invoked.
*** This is disallowed by the MPI standard.
*** Your MPI job will now abort.
[comet-20-55.sdsc.edu:30735] Local abort after MPI_FINALIZE started completed successfully, but am not able to aggregate error messages, and not able to guarantee that all other processes were killed!
*** The MPI_File_close() function was called after MPI_FINALIZE was invoked.
*** This is disallowed by the MPI standard.
*** Your MPI job will now abort.
[comet-20-55.sdsc.edu:30747] Local abort after MPI_FINALIZE started completed successfully, but am not able to aggregate error messages, and not able to guarantee that all other processes were killed!
*** The MPI_File_close() function was called after MPI_FINALIZE was invoked.
*** This is disallowed by the MPI standard.
*** Your MPI job will now abort.
[comet-20-55.sdsc.edu:30740] Local abort after MPI_FINALIZE started completed successfully, but am not able to aggregate error messages, and not able to guarantee that all other processes were killed!
*** The MPI_File_close() function was called after MPI_FINALIZE was invoked.
*** This is disallowed by the MPI standard.
*** Your MPI job will now abort.
[comet-20-55.sdsc.edu:30731] Local abort after MPI_FINALIZE started completed successfully, but am not able to aggregate error messages, and not able to guarantee that all other processes were killed!
*** The MPI_File_close() function was called after MPI_FINALIZE was invoked.
*** This is disallowed by the MPI standard.
*** Your MPI job will now abort.
[comet-20-55.sdsc.edu:30745] Local abort after MPI_FINALIZE started completed successfully, but am not able to aggregate error messages, and not able to guarantee that all other processes were killed!
*** The MPI_File_close() function was called after MPI_FINALIZE was invoked.
*** This is disallowed by the MPI standard.
*** Your MPI job will now abort.
[comet-20-55.sdsc.edu:30752] Local abort after MPI_FINALIZE started completed successfully, but am not able to aggregate error messages, and not able to guarantee that all other processes were killed!
*** The MPI_File_close() function was called after MPI_FINALIZE was invoked.
*** This is disallowed by the MPI standard.
*** Your MPI job will now abort.
[comet-20-55.sdsc.edu:30750] Local abort after MPI_FINALIZE started completed successfully, but am not able to aggregate error messages, and not able to guarantee that all other processes were killed!
--------------------------------------------------------------------------
orterun detected that one or more processes exited with non-zero status, thus causing
the job to be terminated. The first process to do so was:

  Process name: [[15770,1],4]
  Exit code:    1
--------------------------------------------------------------------------

real	1m15.489s
user	0m25.831s
sys	0m11.723s
+ rm -r /oasis/scratch/comet/edisj/temp_project/stripe24/38386559
